ply
format ascii 1.0
comment : MagicaVoxel @ Ephtracy
element vertex 4747
property float x
property float y
property float z
property uchar red
property uchar green
property uchar blue
end_header
-16 -16 0 110 77 55
-15 -16 0 110 77 55
-14 -16 0 110 77 55
-13 -16 0 110 77 55
-12 -16 0 110 77 55
-11 -16 0 110 77 55
-10 -16 0 110 77 55
-9 -16 0 110 77 55
-8 -16 0 110 77 55
-7 -16 0 110 77 55
-6 -16 0 110 77 55
-5 -16 0 110 77 55
-4 -16 0 110 77 55
-3 -16 0 110 77 55
-2 -16 0 110 77 55
-1 -16 0 110 77 55
0 -16 0 110 77 55
1 -16 0 110 77 55
2 -16 0 110 77 55
3 -16 0 110 77 55
4 -16 0 110 77 55
5 -16 0 110 77 55
6 -16 0 110 77 55
7 -16 0 110 77 55
8 -16 0 110 77 55
9 -16 0 110 77 55
10 -16 0 110 77 55
11 -16 0 110 77 55
12 -16 0 110 77 55
13 -16 0 110 77 55
14 -16 0 110 77 55
15 -16 0 136 83 31
-16 -15 0 110 77 55
-15 -15 0 172 140 102
-14 -15 0 172 140 102
-13 -15 0 172 140 102
-12 -15 0 172 140 102
-11 -15 0 172 140 102
-10 -15 0 172 140 102
-9 -15 0 172 140 102
-8 -15 0 172 140 102
-7 -15 0 172 140 102
-6 -15 0 172 140 102
-5 -15 0 172 140 102
-4 -15 0 172 140 102
-3 -15 0 172 140 102
-2 -15 0 172 140 102
-1 -15 0 110 77 55
0 -15 0 172 140 102
1 -15 0 172 140 102
2 -15 0 172 140 102
3 -15 0 172 140 102
4 -15 0 172 140 102
5 -15 0 172 140 102
6 -15 0 172 140 102
7 -15 0 172 140 102
8 -15 0 172 140 102
9 -15 0 172 140 102
10 -15 0 172 140 102
11 -15 0 172 140 102
12 -15 0 172 140 102
13 -15 0 172 140 102
14 -15 0 172 140 102
15 -15 0 136 83 31
-16 -14 0 110 77 55
-15 -14 0 172 140 102
-14 -14 0 218 203 193
-13 -14 0 218 203 193
-12 -14 0 218 203 193
-11 -14 0 218 203 193
-10 -14 0 218 203 193
-9 -14 0 218 203 193
-8 -14 0 218 203 193
-7 -14 0 218 203 193
-6 -14 0 218 203 193
-5 -14 0 218 203 193
-4 -14 0 218 203 193
-3 -14 0 218 203 193
-2 -14 0 172 140 102
-1 -14 0 110 77 55
0 -14 0 172 140 102
1 -14 0 218 203 193
2 -14 0 218 203 193
3 -14 0 218 203 193
4 -14 0 218 203 193
5 -14 0 218 203 193
6 -14 0 218 203 193
7 -14 0 218 203 193
8 -14 0 218 203 193
9 -14 0 218 203 193
10 -14 0 218 203 193
11 -14 0 218 203 193
12 -14 0 218 203 193
13 -14 0 172 140 102
14 -14 0 172 140 102
15 -14 0 136 83 31
-16 -13 0 110 77 55
-15 -13 0 172 140 102
-14 -13 0 218 203 193
-13 -13 0 172 140 102
-12 -13 0 172 140 102
-11 -13 0 172 140 102
-10 -13 0 172 140 102
-9 -13 0 172 140 102
-8 -13 0 172 140 102
-7 -13 0 172 140 102
-6 -13 0 172 140 102
-5 -13 0 172 140 102
-4 -13 0 172 140 102
-3 -13 0 218 203 193
-2 -13 0 172 140 102
-1 -13 0 110 77 55
0 -13 0 172 140 102
1 -13 0 218 203 193
2 -13 0 172 140 102
3 -13 0 172 140 102
4 -13 0 172 140 102
5 -13 0 172 140 102
6 -13 0 172 140 102
7 -13 0 172 140 102
8 -13 0 172 140 102
9 -13 0 172 140 102
10 -13 0 172 140 102
11 -13 0 172 140 102
12 -13 0 218 203 193
13 -13 0 172 140 102
14 -13 0 172 140 102
15 -13 0 136 83 31
-16 -12 0 110 77 55
-15 -12 0 172 140 102
-14 -12 0 218 203 193
-13 -12 0 172 140 102
-12 -12 0 230 221 158
-11 -12 0 172 140 102
-10 -12 0 230 221 158
-9 -12 0 172 140 102
-8 -12 0 172 140 102
-7 -12 0 230 221 158
-6 -12 0 172 140 102
-5 -12 0 230 221 158
-4 -12 0 172 140 102
-3 -12 0 218 203 193
-2 -12 0 172 140 102
-1 -12 0 110 77 55
0 -12 0 172 140 102
1 -12 0 218 203 193
2 -12 0 172 140 102
3 -12 0 230 221 158
4 -12 0 172 140 102
5 -12 0 230 221 158
6 -12 0 172 140 102
7 -12 0 172 140 102
8 -12 0 230 221 158
9 -12 0 172 140 102
10 -12 0 230 221 158
11 -12 0 172 140 102
12 -12 0 218 203 193
13 -12 0 172 140 102
14 -12 0 172 140 102
15 -12 0 136 83 31
-16 -11 0 110 77 55
-15 -11 0 172 140 102
-14 -11 0 218 203 193
-13 -11 0 172 140 102
-12 -11 0 172 140 102
-11 -11 0 230 221 158
-10 -11 0 172 140 102
-9 -11 0 172 140 102
-8 -11 0 172 140 102
-7 -11 0 172 140 102
-6 -11 0 230 221 158
-5 -11 0 172 140 102
-4 -11 0 172 140 102
-3 -11 0 218 203 193
-2 -11 0 172 140 102
-1 -11 0 110 77 55
0 -11 0 172 140 102
1 -11 0 218 203 193
2 -11 0 172 140 102
3 -11 0 172 140 102
4 -11 0 230 221 158
5 -11 0 172 140 102
6 -11 0 172 140 102
7 -11 0 172 140 102
8 -11 0 172 140 102
9 -11 0 230 221 158
10 -11 0 172 140 102
11 -11 0 172 140 102
12 -11 0 218 203 193
13 -11 0 172 140 102
14 -11 0 172 140 102
15 -11 0 136 83 31
-16 -10 0 110 77 55
-15 -10 0 172 140 102
-14 -10 0 218 203 193
-13 -10 0 172 140 102
-12 -10 0 230 221 158
-11 -10 0 172 140 102
-10 -10 0 230 221 158
-9 -10 0 172 140 102
-8 -10 0 244 229 199
-7 -10 0 230 221 158
-6 -10 0 172 140 102
-5 -10 0 230 221 158
-4 -10 0 172 140 102
-3 -10 0 218 203 193
-2 -10 0 172 140 102
-1 -10 0 110 77 55
0 -10 0 172 140 102
1 -10 0 218 203 193
2 -10 0 172 140 102
3 -10 0 230 221 158
4 -10 0 172 140 102
5 -10 0 230 221 158
6 -10 0 244 229 199
7 -10 0 172 140 102
8 -10 0 230 221 158
9 -10 0 172 140 102
10 -10 0 230 221 158
11 -10 0 172 140 102
12 -10 0 218 203 193
13 -10 0 172 140 102
14 -10 0 172 140 102
15 -10 0 136 83 31
-16 -9 0 110 77 55
-15 -9 0 172 140 102
-14 -9 0 218 203 193
-13 -9 0 172 140 102
-12 -9 0 172 140 102
-11 -9 0 172 140 102
-10 -9 0 172 140 102
-9 -9 0 230 221 158
-8 -9 0 230 221 158
-7 -9 0 244 229 199
-6 -9 0 172 140 102
-5 -9 0 172 140 102
-4 -9 0 172 140 102
-3 -9 0 218 203 193
-2 -9 0 172 140 102
-1 -9 0 110 77 55
0 -9 0 172 140 102
1 -9 0 218 203 193
2 -9 0 172 140 102
3 -9 0 172 140 102
4 -9 0 172 140 102
5 -9 0 244 229 199
6 -9 0 230 221 158
7 -9 0 230 221 158
8 -9 0 172 140 102
9 -9 0 172 140 102
10 -9 0 172 140 102
11 -9 0 172 140 102
12 -9 0 218 203 193
13 -9 0 172 140 102
14 -9 0 172 140 102
15 -9 0 136 83 31
-16 -8 0 110 77 55
-15 -8 0 172 140 102
-14 -8 0 218 203 193
-13 -8 0 172 140 102
-12 -8 0 172 140 102
-11 -8 0 172 140 102
-10 -8 0 244 229 199
-9 -8 0 230 221 158
-8 -8 0 230 221 158
-7 -8 0 172 140 102
-6 -8 0 172 140 102
-5 -8 0 172 140 102
-4 -8 0 172 140 102
-3 -8 0 218 203 193
-2 -8 0 172 140 102
-1 -8 0 110 77 55
0 -8 0 172 140 102
1 -8 0 218 203 193
2 -8 0 172 140 102
3 -8 0 172 140 102
4 -8 0 172 140 102
5 -8 0 172 140 102
6 -8 0 230 221 158
7 -8 0 230 221 158
8 -8 0 244 229 199
9 -8 0 172 140 102
10 -8 0 172 140 102
11 -8 0 172 140 102
12 -8 0 218 203 193
13 -8 0 172 140 102
14 -8 0 172 140 102
15 -8 0 136 83 31
-16 -7 0 110 77 55
-15 -7 0 172 140 102
-14 -7 0 218 203 193
-13 -7 0 172 140 102
-12 -7 0 230 221 158
-11 -7 0 172 140 102
-10 -7 0 230 221 158
-9 -7 0 244 229 199
-8 -7 0 172 140 102
-7 -7 0 230 221 158
-6 -7 0 172 140 102
-5 -7 0 230 221 158
-4 -7 0 172 140 102
-3 -7 0 218 203 193
-2 -7 0 172 140 102
-1 -7 0 110 77 55
0 -7 0 172 140 102
1 -7 0 218 203 193
2 -7 0 172 140 102
3 -7 0 230 221 158
4 -7 0 172 140 102
5 -7 0 230 221 158
6 -7 0 172 140 102
7 -7 0 244 229 199
8 -7 0 230 221 158
9 -7 0 172 140 102
10 -7 0 230 221 158
11 -7 0 172 140 102
12 -7 0 218 203 193
13 -7 0 172 140 102
14 -7 0 172 140 102
15 -7 0 136 83 31
-16 -6 0 110 77 55
-15 -6 0 172 140 102
-14 -6 0 218 203 193
-13 -6 0 172 140 102
-12 -6 0 172 140 102
-11 -6 0 230 221 158
-10 -6 0 172 140 102
-9 -6 0 172 140 102
-8 -6 0 172 140 102
-7 -6 0 172 140 102
-6 -6 0 230 221 158
-5 -6 0 172 140 102
-4 -6 0 172 140 102
-3 -6 0 218 203 193
-2 -6 0 172 140 102
-1 -6 0 110 77 55
0 -6 0 172 140 102
1 -6 0 218 203 193
2 -6 0 172 140 102
3 -6 0 172 140 102
4 -6 0 230 221 158
5 -6 0 172 140 102
6 -6 0 172 140 102
7 -6 0 172 140 102
8 -6 0 172 140 102
9 -6 0 230 221 158
10 -6 0 172 140 102
11 -6 0 172 140 102
12 -6 0 218 203 193
13 -6 0 172 140 102
14 -6 0 172 140 102
15 -6 0 136 83 31
-16 -5 0 110 77 55
-15 -5 0 172 140 102
-14 -5 0 218 203 193
-13 -5 0 172 140 102
-12 -5 0 230 221 158
-11 -5 0 172 140 102
-10 -5 0 230 221 158
-9 -5 0 172 140 102
-8 -5 0 172 140 102
-7 -5 0 230 221 158
-6 -5 0 172 140 102
-5 -5 0 230 221 158
-4 -5 0 172 140 102
-3 -5 0 218 203 193
-2 -5 0 172 140 102
-1 -5 0 110 77 55
0 -5 0 172 140 102
1 -5 0 218 203 193
2 -5 0 172 140 102
3 -5 0 230 221 158
4 -5 0 172 140 102
5 -5 0 230 221 158
6 -5 0 172 140 102
7 -5 0 172 140 102
8 -5 0 230 221 158
9 -5 0 172 140 102
10 -5 0 230 221 158
11 -5 0 172 140 102
12 -5 0 218 203 193
13 -5 0 172 140 102
14 -5 0 172 140 102
15 -5 0 136 83 31
-16 -4 0 110 77 55
-15 -4 0 172 140 102
-14 -4 0 218 203 193
-13 -4 0 172 140 102
-12 -4 0 172 140 102
-11 -4 0 172 140 102
-10 -4 0 172 140 102
-9 -4 0 172 140 102
-8 -4 0 172 140 102
-7 -4 0 172 140 102
-6 -4 0 172 140 102
-5 -4 0 172 140 102
-4 -4 0 172 140 102
-3 -4 0 218 203 193
-2 -4 0 172 140 102
-1 -4 0 110 77 55
0 -4 0 172 140 102
1 -4 0 218 203 193
2 -4 0 172 140 102
3 -4 0 172 140 102
4 -4 0 172 140 102
5 -4 0 172 140 102
6 -4 0 172 140 102
7 -4 0 172 140 102
8 -4 0 172 140 102
9 -4 0 172 140 102
10 -4 0 172 140 102
11 -4 0 172 140 102
12 -4 0 218 203 193
13 -4 0 172 140 102
14 -4 0 172 140 102
15 -4 0 136 83 31
-16 -3 0 110 77 55
-15 -3 0 172 140 102
-14 -3 0 218 203 193
-13 -3 0 218 203 193
-12 -3 0 218 203 193
-11 -3 0 218 203 193
-10 -3 0 218 203 193
-9 -3 0 218 203 193
-8 -3 0 218 203 193
-7 -3 0 218 203 193
-6 -3 0 218 203 193
-5 -3 0 218 203 193
-4 -3 0 218 203 193
-3 -3 0 218 203 193
-2 -3 0 172 140 102
-1 -3 0 110 77 55
0 -3 0 172 140 102
1 -3 0 218 203 193
2 -3 0 218 203 193
3 -3 0 218 203 193
4 -3 0 218 203 193
5 -3 0 218 203 193
6 -3 0 218 203 193
7 -3 0 218 203 193
8 -3 0 218 203 193
9 -3 0 218 203 193
10 -3 0 218 203 193
11 -3 0 218 203 193
12 -3 0 218 203 193
13 -3 0 172 140 102
14 -3 0 172 140 102
15 -3 0 136 83 31
-16 -2 0 110 77 55
-15 -2 0 172 140 102
-14 -2 0 172 140 102
-13 -2 0 172 140 102
-12 -2 0 172 140 102
-11 -2 0 172 140 102
-10 -2 0 172 140 102
-9 -2 0 172 140 102
-8 -2 0 172 140 102
-7 -2 0 172 140 102
-6 -2 0 172 140 102
-5 -2 0 172 140 102
-4 -2 0 172 140 102
-3 -2 0 172 140 102
-2 -2 0 172 140 102
-1 -2 0 110 77 55
0 -2 0 172 140 102
1 -2 0 172 140 102
2 -2 0 172 140 102
3 -2 0 172 140 102
4 -2 0 172 140 102
5 -2 0 172 140 102
6 -2 0 172 140 102
7 -2 0 172 140 102
8 -2 0 172 140 102
9 -2 0 172 140 102
10 -2 0 172 140 102
11 -2 0 172 140 102
12 -2 0 172 140 102
13 -2 0 172 140 102
14 -2 0 172 140 102
15 -2 0 136 83 31
-16 -1 0 110 77 55
-15 -1 0 110 77 55
-14 -1 0 110 77 55
-13 -1 0 110 77 55
-12 -1 0 110 77 55
-11 -1 0 110 77 55
-10 -1 0 110 77 55
-9 -1 0 110 77 55
-8 -1 0 110 77 55
-7 -1 0 110 77 55
-6 -1 0 110 77 55
-5 -1 0 110 77 55
-4 -1 0 110 77 55
-3 -1 0 110 77 55
-2 -1 0 110 77 55
-1 -1 0 110 77 55
0 -1 0 110 77 55
1 -1 0 110 77 55
2 -1 0 110 77 55
3 -1 0 110 77 55
4 -1 0 110 77 55
5 -1 0 110 77 55
6 -1 0 110 77 55
7 -1 0 110 77 55
8 -1 0 110 77 55
9 -1 0 110 77 55
10 -1 0 110 77 55
11 -1 0 110 77 55
12 -1 0 110 77 55
13 -1 0 110 77 55
14 -1 0 110 77 55
15 -1 0 136 83 31
-16 0 0 110 77 55
-15 0 0 172 140 102
-14 0 0 172 140 102
-13 0 0 172 140 102
-12 0 0 172 140 102
-11 0 0 172 140 102
-10 0 0 172 140 102
-9 0 0 172 140 102
-8 0 0 172 140 102
-7 0 0 172 140 102
-6 0 0 172 140 102
-5 0 0 172 140 102
-4 0 0 172 140 102
-3 0 0 172 140 102
-2 0 0 172 140 102
-1 0 0 110 77 55
0 0 0 172 140 102
1 0 0 172 140 102
2 0 0 172 140 102
3 0 0 172 140 102
4 0 0 172 140 102
5 0 0 172 140 102
6 0 0 172 140 102
7 0 0 172 140 102
8 0 0 172 140 102
9 0 0 172 140 102
10 0 0 172 140 102
11 0 0 172 140 102
12 0 0 172 140 102
13 0 0 172 140 102
14 0 0 172 140 102
15 0 0 136 83 31
-16 1 0 110 77 55
-15 1 0 172 140 102
-14 1 0 218 203 193
-13 1 0 218 203 193
-12 1 0 218 203 193
-11 1 0 218 203 193
-10 1 0 218 203 193
-9 1 0 218 203 193
-8 1 0 218 203 193
-7 1 0 218 203 193
-6 1 0 218 203 193
-5 1 0 218 203 193
-4 1 0 218 203 193
-3 1 0 218 203 193
-2 1 0 172 140 102
-1 1 0 110 77 55
0 1 0 172 140 102
1 1 0 218 203 193
2 1 0 218 203 193
3 1 0 218 203 193
4 1 0 218 203 193
5 1 0 218 203 193
6 1 0 218 203 193
7 1 0 218 203 193
8 1 0 218 203 193
9 1 0 218 203 193
10 1 0 218 203 193
11 1 0 218 203 193
12 1 0 218 203 193
13 1 0 172 140 102
14 1 0 172 140 102
15 1 0 136 83 31
-16 2 0 110 77 55
-15 2 0 172 140 102
-14 2 0 218 203 193
-13 2 0 172 140 102
-12 2 0 172 140 102
-11 2 0 172 140 102
-10 2 0 172 140 102
-9 2 0 172 140 102
-8 2 0 172 140 102
-7 2 0 172 140 102
-6 2 0 172 140 102
-5 2 0 172 140 102
-4 2 0 172 140 102
-3 2 0 218 203 193
-2 2 0 172 140 102
-1 2 0 110 77 55
0 2 0 172 140 102
1 2 0 218 203 193
2 2 0 172 140 102
3 2 0 172 140 102
4 2 0 172 140 102
5 2 0 172 140 102
6 2 0 172 140 102
7 2 0 172 140 102
8 2 0 172 140 102
9 2 0 172 140 102
10 2 0 172 140 102
11 2 0 172 140 102
12 2 0 218 203 193
13 2 0 172 140 102
14 2 0 172 140 102
15 2 0 136 83 31
-16 3 0 110 77 55
-15 3 0 172 140 102
-14 3 0 218 203 193
-13 3 0 172 140 102
-12 3 0 230 221 158
-11 3 0 172 140 102
-10 3 0 230 221 158
-9 3 0 172 140 102
-8 3 0 172 140 102
-7 3 0 230 221 158
-6 3 0 172 140 102
-5 3 0 230 221 158
-4 3 0 172 140 102
-3 3 0 218 203 193
-2 3 0 172 140 102
-1 3 0 110 77 55
0 3 0 172 140 102
1 3 0 218 203 193
2 3 0 172 140 102
3 3 0 230 221 158
4 3 0 172 140 102
5 3 0 230 221 158
6 3 0 172 140 102
7 3 0 172 140 102
8 3 0 230 221 158
9 3 0 172 140 102
10 3 0 230 221 158
11 3 0 172 140 102
12 3 0 218 203 193
13 3 0 172 140 102
14 3 0 172 140 102
15 3 0 136 83 31
-16 4 0 110 77 55
-15 4 0 172 140 102
-14 4 0 218 203 193
-13 4 0 172 140 102
-12 4 0 172 140 102
-11 4 0 230 221 158
-10 4 0 172 140 102
-9 4 0 172 140 102
-8 4 0 172 140 102
-7 4 0 172 140 102
-6 4 0 230 221 158
-5 4 0 172 140 102
-4 4 0 172 140 102
-3 4 0 218 203 193
-2 4 0 172 140 102
-1 4 0 110 77 55
0 4 0 172 140 102
1 4 0 218 203 193
2 4 0 172 140 102
3 4 0 172 140 102
4 4 0 230 221 158
5 4 0 172 140 102
6 4 0 172 140 102
7 4 0 172 140 102
8 4 0 172 140 102
9 4 0 230 221 158
10 4 0 172 140 102
11 4 0 172 140 102
12 4 0 218 203 193
13 4 0 172 140 102
14 4 0 172 140 102
15 4 0 136 83 31
-16 5 0 110 77 55
-15 5 0 172 140 102
-14 5 0 218 203 193
-13 5 0 172 140 102
-12 5 0 230 221 158
-11 5 0 172 140 102
-10 5 0 230 221 158
-9 5 0 244 229 199
-8 5 0 172 140 102
-7 5 0 230 221 158
-6 5 0 172 140 102
-5 5 0 230 221 158
-4 5 0 172 140 102
-3 5 0 218 203 193
-2 5 0 172 140 102
-1 5 0 110 77 55
0 5 0 172 140 102
1 5 0 218 203 193
2 5 0 172 140 102
3 5 0 230 221 158
4 5 0 172 140 102
5 5 0 230 221 158
6 5 0 172 140 102
7 5 0 244 229 199
8 5 0 230 221 158
9 5 0 172 140 102
10 5 0 230 221 158
11 5 0 172 140 102
12 5 0 218 203 193
13 5 0 172 140 102
14 5 0 172 140 102
15 5 0 136 83 31
-16 6 0 110 77 55
-15 6 0 172 140 102
-14 6 0 218 203 193
-13 6 0 172 140 102
-12 6 0 172 140 102
-11 6 0 172 140 102
-10 6 0 244 229 199
-9 6 0 230 221 158
-8 6 0 230 221 158
-7 6 0 172 140 102
-6 6 0 172 140 102
-5 6 0 172 140 102
-4 6 0 172 140 102
-3 6 0 218 203 193
-2 6 0 172 140 102
-1 6 0 110 77 55
0 6 0 172 140 102
1 6 0 218 203 193
2 6 0 172 140 102
3 6 0 172 140 102
4 6 0 172 140 102
5 6 0 172 140 102
6 6 0 230 221 158
7 6 0 230 221 158
8 6 0 244 229 199
9 6 0 172 140 102
10 6 0 172 140 102
11 6 0 172 140 102
12 6 0 218 203 193
13 6 0 172 140 102
14 6 0 172 140 102
15 6 0 136 83 31
-16 7 0 110 77 55
-15 7 0 172 140 102
-14 7 0 218 203 193
-13 7 0 172 140 102
-12 7 0 172 140 102
-11 7 0 172 140 102
-10 7 0 172 140 102
-9 7 0 230 221 158
-8 7 0 230 221 158
-7 7 0 244 229 199
-6 7 0 172 140 102
-5 7 0 172 140 102
-4 7 0 172 140 102
-3 7 0 218 203 193
-2 7 0 172 140 102
-1 7 0 110 77 55
0 7 0 172 140 102
1 7 0 218 203 193
2 7 0 172 140 102
3 7 0 172 140 102
4 7 0 172 140 102
5 7 0 244 229 199
6 7 0 230 221 158
7 7 0 230 221 158
8 7 0 172 140 102
9 7 0 172 140 102
10 7 0 172 140 102
11 7 0 172 140 102
12 7 0 218 203 193
13 7 0 172 140 102
14 7 0 172 140 102
15 7 0 136 83 31
-16 8 0 110 77 55
-15 8 0 172 140 102
-14 8 0 218 203 193
-13 8 0 172 140 102
-12 8 0 230 221 158
-11 8 0 172 140 102
-10 8 0 230 221 158
-9 8 0 172 140 102
-8 8 0 244 229 199
-7 8 0 230 221 158
-6 8 0 172 140 102
-5 8 0 230 221 158
-4 8 0 172 140 102
-3 8 0 218 203 193
-2 8 0 172 140 102
-1 8 0 110 77 55
0 8 0 172 140 102
1 8 0 218 203 193
2 8 0 172 140 102
3 8 0 230 221 158
4 8 0 172 140 102
5 8 0 230 221 158
6 8 0 244 229 199
7 8 0 172 140 102
8 8 0 230 221 158
9 8 0 172 140 102
10 8 0 230 221 158
11 8 0 172 140 102
12 8 0 218 203 193
13 8 0 172 140 102
14 8 0 172 140 102
15 8 0 136 83 31
-16 9 0 110 77 55
-15 9 0 172 140 102
-14 9 0 218 203 193
-13 9 0 172 140 102
-12 9 0 172 140 102
-11 9 0 230 221 158
-10 9 0 172 140 102
-9 9 0 172 140 102
-8 9 0 172 140 102
-7 9 0 172 140 102
-6 9 0 230 221 158
-5 9 0 172 140 102
-4 9 0 172 140 102
-3 9 0 218 203 193
-2 9 0 172 140 102
-1 9 0 110 77 55
0 9 0 172 140 102
1 9 0 218 203 193
2 9 0 172 140 102
3 9 0 172 140 102
4 9 0 230 221 158
5 9 0 172 140 102
6 9 0 172 140 102
7 9 0 172 140 102
8 9 0 172 140 102
9 9 0 230 221 158
10 9 0 172 140 102
11 9 0 172 140 102
12 9 0 218 203 193
13 9 0 172 140 102
14 9 0 172 140 102
15 9 0 136 83 31
-16 10 0 110 77 55
-15 10 0 172 140 102
-14 10 0 218 203 193
-13 10 0 172 140 102
-12 10 0 230 221 158
-11 10 0 172 140 102
-10 10 0 230 221 158
-9 10 0 172 140 102
-8 10 0 172 140 102
-7 10 0 230 221 158
-6 10 0 172 140 102
-5 10 0 230 221 158
-4 10 0 172 140 102
-3 10 0 218 203 193
-2 10 0 172 140 102
-1 10 0 110 77 55
0 10 0 172 140 102
1 10 0 218 203 193
2 10 0 172 140 102
3 10 0 230 221 158
4 10 0 172 140 102
5 10 0 230 221 158
6 10 0 172 140 102
7 10 0 172 140 102
8 10 0 230 221 158
9 10 0 172 140 102
10 10 0 230 221 158
11 10 0 172 140 102
12 10 0 218 203 193
13 10 0 172 140 102
14 10 0 172 140 102
15 10 0 136 83 31
-16 11 0 110 77 55
-15 11 0 172 140 102
-14 11 0 218 203 193
-13 11 0 172 140 102
-12 11 0 172 140 102
-11 11 0 172 140 102
-10 11 0 172 140 102
-9 11 0 172 140 102
-8 11 0 172 140 102
-7 11 0 172 140 102
-6 11 0 172 140 102
-5 11 0 172 140 102
-4 11 0 172 140 102
-3 11 0 218 203 193
-2 11 0 172 140 102
-1 11 0 110 77 55
0 11 0 172 140 102
1 11 0 218 203 193
2 11 0 172 140 102
3 11 0 172 140 102
4 11 0 172 140 102
5 11 0 172 140 102
6 11 0 172 140 102
7 11 0 172 140 102
8 11 0 172 140 102
9 11 0 172 140 102
10 11 0 172 140 102
11 11 0 172 140 102
12 11 0 218 203 193
13 11 0 172 140 102
14 11 0 172 140 102
15 11 0 136 83 31
-16 12 0 110 77 55
-15 12 0 172 140 102
-14 12 0 218 203 193
-13 12 0 218 203 193
-12 12 0 218 203 193
-11 12 0 218 203 193
-10 12 0 218 203 193
-9 12 0 218 203 193
-8 12 0 218 203 193
-7 12 0 218 203 193
-6 12 0 218 203 193
-5 12 0 218 203 193
-4 12 0 218 203 193
-3 12 0 218 203 193
-2 12 0 172 140 102
-1 12 0 110 77 55
0 12 0 172 140 102
1 12 0 218 203 193
2 12 0 218 203 193
3 12 0 218 203 193
4 12 0 218 203 193
5 12 0 218 203 193
6 12 0 218 203 193
7 12 0 218 203 193
8 12 0 218 203 193
9 12 0 218 203 193
10 12 0 218 203 193
11 12 0 218 203 193
12 12 0 218 203 193
13 12 0 172 140 102
14 12 0 172 140 102
15 12 0 136 83 31
-16 13 0 110 77 55
-15 13 0 172 140 102
-14 13 0 172 140 102
-13 13 0 172 140 102
-12 13 0 172 140 102
-11 13 0 172 140 102
-10 13 0 172 140 102
-9 13 0 172 140 102
-8 13 0 172 140 102
-7 13 0 172 140 102
-6 13 0 172 140 102
-5 13 0 172 140 102
-4 13 0 172 140 102
-3 13 0 172 140 102
-2 13 0 172 140 102
-1 13 0 110 77 55
0 13 0 172 140 102
1 13 0 172 140 102
2 13 0 172 140 102
3 13 0 172 140 102
4 13 0 172 140 102
5 13 0 172 140 102
6 13 0 172 140 102
7 13 0 172 140 102
8 13 0 172 140 102
9 13 0 172 140 102
10 13 0 172 140 102
11 13 0 172 140 102
12 13 0 172 140 102
13 13 0 172 140 102
14 13 0 172 140 102
15 13 0 136 83 31
-16 14 0 110 77 55
-15 14 0 172 140 102
-14 14 0 172 140 102
-13 14 0 172 140 102
-12 14 0 172 140 102
-11 14 0 172 140 102
-10 14 0 172 140 102
-9 14 0 172 140 102
-8 14 0 172 140 102
-7 14 0 172 140 102
-6 14 0 172 140 102
-5 14 0 172 140 102
-4 14 0 172 140 102
-3 14 0 172 140 102
-2 14 0 172 140 102
-1 14 0 110 77 55
0 14 0 172 140 102
1 14 0 172 140 102
2 14 0 172 140 102
3 14 0 172 140 102
4 14 0 172 140 102
5 14 0 172 140 102
6 14 0 172 140 102
7 14 0 172 140 102
8 14 0 172 140 102
9 14 0 172 140 102
10 14 0 172 140 102
11 14 0 172 140 102
12 14 0 172 140 102
13 14 0 172 140 102
14 14 0 172 140 102
15 14 0 136 83 31
-16 15 0 136 83 31
-15 15 0 136 83 31
-14 15 0 136 83 31
-13 15 0 136 83 31
-12 15 0 136 83 31
-11 15 0 136 83 31
-10 15 0 136 83 31
-9 15 0 136 83 31
-8 15 0 136 83 31
-7 15 0 136 83 31
-6 15 0 136 83 31
-5 15 0 136 83 31
-4 15 0 136 83 31
-3 15 0 136 83 31
-2 15 0 136 83 31
-1 15 0 136 83 31
0 15 0 136 83 31
1 15 0 136 83 31
2 15 0 136 83 31
3 15 0 136 83 31
4 15 0 136 83 31
5 15 0 136 83 31
6 15 0 136 83 31
7 15 0 136 83 31
8 15 0 136 83 31
9 15 0 136 83 31
10 15 0 136 83 31
11 15 0 136 83 31
12 15 0 136 83 31
13 15 0 136 83 31
14 15 0 136 83 31
15 15 0 136 83 31
15 -16 1 136 83 31
15 -15 1 136 83 31
14 -14 1 93 50 19
15 -14 1 136 83 31
3 -13 1 255 255 255
4 -13 1 255 255 255
5 -13 1 255 255 255
6 -13 1 255 255 255
7 -13 1 159 49 30
8 -13 1 159 49 30
15 -13 1 136 83 31
-3 -12 1 93 50 19
-2 -12 1 93 50 19
-1 -12 1 93 50 19
0 -12 1 93 50 19
1 -12 1 93 50 19
2 -12 1 93 50 19
3 -12 1 93 50 19
4 -12 1 93 50 19
5 -12 1 93 50 19
6 -12 1 93 50 19
7 -12 1 93 50 19
8 -12 1 93 50 19
9 -12 1 93 50 19
10 -12 1 93 50 19
11 -12 1 93 50 19
12 -12 1 93 50 19
13 -12 1 93 50 19
14 -12 1 93 50 19
15 -12 1 136 83 31
-3 -11 1 93 50 19
-2 -11 1 93 50 19
-1 -11 1 93 50 19
0 -11 1 93 50 19
1 -11 1 93 50 19
2 -11 1 93 50 19
3 -11 1 93 50 19
4 -11 1 93 50 19
5 -11 1 93 50 19
6 -11 1 93 50 19
7 -11 1 93 50 19
8 -11 1 93 50 19
9 -11 1 93 50 19
10 -11 1 93 50 19
11 -11 1 93 50 19
12 -11 1 93 50 19
13 -11 1 93 50 19
14 -11 1 93 50 19
15 -11 1 136 83 31
-3 -10 1 93 50 19
-2 -10 1 93 50 19
-1 -10 1 93 50 19
0 -10 1 93 50 19
1 -10 1 93 50 19
2 -10 1 93 50 19
3 -10 1 93 50 19
4 -10 1 93 50 19
5 -10 1 93 50 19
6 -10 1 93 50 19
7 -10 1 93 50 19
8 -10 1 93 50 19
9 -10 1 93 50 19
10 -10 1 93 50 19
11 -10 1 93 50 19
12 -10 1 93 50 19
13 -10 1 93 50 19
14 -10 1 93 50 19
15 -10 1 136 83 31
-3 -9 1 93 50 19
-2 -9 1 93 50 19
-1 -9 1 93 50 19
0 -9 1 93 50 19
1 -9 1 93 50 19
2 -9 1 93 50 19
3 -9 1 93 50 19
4 -9 1 93 50 19
5 -9 1 93 50 19
6 -9 1 93 50 19
7 -9 1 93 50 19
8 -9 1 93 50 19
9 -9 1 93 50 19
10 -9 1 93 50 19
11 -9 1 93 50 19
12 -9 1 93 50 19
13 -9 1 93 50 19
14 -9 1 93 50 19
15 -9 1 136 83 31
-3 -8 1 93 50 19
-2 -8 1 93 50 19
-1 -8 1 93 50 19
0 -8 1 93 50 19
1 -8 1 93 50 19
2 -8 1 93 50 19
3 -8 1 93 50 19
4 -8 1 93 50 19
5 -8 1 93 50 19
6 -8 1 93 50 19
7 -8 1 93 50 19
8 -8 1 93 50 19
9 -8 1 93 50 19
10 -8 1 93 50 19
11 -8 1 93 50 19
12 -8 1 93 50 19
13 -8 1 93 50 19
14 -8 1 93 50 19
15 -8 1 136 83 31
-3 -7 1 93 50 19
-2 -7 1 93 50 19
-1 -7 1 93 50 19
0 -7 1 93 50 19
1 -7 1 93 50 19
2 -7 1 93 50 19
3 -7 1 93 50 19
4 -7 1 93 50 19
5 -7 1 93 50 19
6 -7 1 93 50 19
7 -7 1 93 50 19
8 -7 1 93 50 19
9 -7 1 93 50 19
10 -7 1 93 50 19
11 -7 1 93 50 19
12 -7 1 93 50 19
13 -7 1 93 50 19
14 -7 1 93 50 19
15 -7 1 136 83 31
-3 -6 1 93 50 19
-2 -6 1 93 50 19
-1 -6 1 93 50 19
0 -6 1 93 50 19
1 -6 1 93 50 19
2 -6 1 93 50 19
3 -6 1 93 50 19
4 -6 1 93 50 19
5 -6 1 93 50 19
6 -6 1 93 50 19
7 -6 1 93 50 19
8 -6 1 93 50 19
9 -6 1 93 50 19
10 -6 1 93 50 19
11 -6 1 93 50 19
12 -6 1 93 50 19
13 -6 1 93 50 19
14 -6 1 93 50 19
15 -6 1 136 83 31
-3 -5 1 93 50 19
-2 -5 1 93 50 19
-1 -5 1 93 50 19
0 -5 1 93 50 19
1 -5 1 93 50 19
2 -5 1 93 50 19
3 -5 1 93 50 19
4 -5 1 93 50 19
5 -5 1 93 50 19
6 -5 1 93 50 19
7 -5 1 93 50 19
8 -5 1 93 50 19
9 -5 1 93 50 19
10 -5 1 93 50 19
11 -5 1 93 50 19
12 -5 1 93 50 19
13 -5 1 93 50 19
14 -5 1 93 50 19
15 -5 1 136 83 31
-3 -4 1 93 50 19
-2 -4 1 93 50 19
-1 -4 1 93 50 19
0 -4 1 93 50 19
1 -4 1 93 50 19
2 -4 1 93 50 19
3 -4 1 93 50 19
4 -4 1 93 50 19
5 -4 1 93 50 19
6 -4 1 93 50 19
7 -4 1 93 50 19
8 -4 1 93 50 19
9 -4 1 93 50 19
10 -4 1 93 50 19
11 -4 1 93 50 19
12 -4 1 93 50 19
13 -4 1 93 50 19
14 -4 1 93 50 19
15 -4 1 136 83 31
-3 -3 1 93 50 19
-2 -3 1 93 50 19
-1 -3 1 93 50 19
0 -3 1 93 50 19
1 -3 1 93 50 19
2 -3 1 93 50 19
3 -3 1 93 50 19
4 -3 1 93 50 19
5 -3 1 93 50 19
6 -3 1 93 50 19
7 -3 1 93 50 19
8 -3 1 93 50 19
9 -3 1 93 50 19
10 -3 1 93 50 19
11 -3 1 93 50 19
12 -3 1 93 50 19
13 -3 1 93 50 19
14 -3 1 93 50 19
15 -3 1 136 83 31
-3 -2 1 93 50 19
-2 -2 1 93 50 19
-1 -2 1 93 50 19
0 -2 1 93 50 19
1 -2 1 93 50 19
2 -2 1 93 50 19
3 -2 1 93 50 19
4 -2 1 93 50 19
5 -2 1 93 50 19
6 -2 1 93 50 19
7 -2 1 93 50 19
8 -2 1 93 50 19
9 -2 1 93 50 19
10 -2 1 93 50 19
11 -2 1 93 50 19
12 -2 1 93 50 19
13 -2 1 93 50 19
14 -2 1 93 50 19
15 -2 1 136 83 31
-3 -1 1 93 50 19
-2 -1 1 93 50 19
-1 -1 1 93 50 19
0 -1 1 93 50 19
1 -1 1 93 50 19
2 -1 1 93 50 19
3 -1 1 93 50 19
4 -1 1 93 50 19
5 -1 1 93 50 19
6 -1 1 93 50 19
7 -1 1 93 50 19
8 -1 1 93 50 19
9 -1 1 93 50 19
10 -1 1 93 50 19
11 -1 1 93 50 19
12 -1 1 93 50 19
13 -1 1 93 50 19
14 -1 1 93 50 19
15 -1 1 136 83 31
-3 0 1 93 50 19
-2 0 1 93 50 19
-1 0 1 93 50 19
0 0 1 93 50 19
1 0 1 93 50 19
2 0 1 93 50 19
3 0 1 93 50 19
4 0 1 93 50 19
5 0 1 93 50 19
6 0 1 93 50 19
7 0 1 93 50 19
8 0 1 93 50 19
9 0 1 93 50 19
10 0 1 93 50 19
11 0 1 93 50 19
12 0 1 93 50 19
13 0 1 93 50 19
14 0 1 93 50 19
15 0 1 136 83 31
5 1 1 159 49 30
9 1 1 255 255 255
10 1 1 255 255 255
11 1 1 255 255 255
12 1 1 255 255 255
13 1 1 255 255 255
14 1 1 93 50 19
15 1 1 136 83 31
14 2 1 93 50 19
15 2 1 136 83 31
15 3 1 136 83 31
15 4 1 136 83 31
15 5 1 136 83 31
15 6 1 136 83 31
15 7 1 136 83 31
-13 8 1 56 38 31
-7 8 1 56 38 31
15 8 1 136 83 31
15 9 1 136 83 31
1 10 1 93 50 19
11 10 1 93 50 19
15 10 1 136 83 31
15 11 1 136 83 31
15 12 1 136 83 31
15 13 1 136 83 31
-13 14 1 56 38 31
-7 14 1 56 38 31
1 14 1 93 50 19
11 14 1 93 50 19
15 14 1 136 83 31
-16 15 1 136 83 31
-15 15 1 136 83 31
-14 15 1 136 83 31
-13 15 1 136 83 31
-12 15 1 136 83 31
-11 15 1 136 83 31
-10 15 1 136 83 31
-9 15 1 136 83 31
-8 15 1 136 83 31
-7 15 1 136 83 31
-6 15 1 136 83 31
-5 15 1 136 83 31
-4 15 1 136 83 31
-3 15 1 136 83 31
-2 15 1 136 83 31
-1 15 1 136 83 31
0 15 1 136 83 31
1 15 1 136 83 31
2 15 1 136 83 31
3 15 1 136 83 31
4 15 1 136 83 31
5 15 1 136 83 31
6 15 1 136 83 31
7 15 1 136 83 31
8 15 1 136 83 31
9 15 1 136 83 31
10 15 1 136 83 31
11 15 1 136 83 31
12 15 1 136 83 31
13 15 1 136 83 31
14 15 1 136 83 31
15 15 1 215 188 117
15 -16 2 136 83 31
15 -15 2 215 188 117
14 -14 2 93 50 19
15 -14 2 215 188 117
-1 -13 2 255 255 255
0 -13 2 255 255 255
1 -13 2 255 255 255
2 -13 2 255 255 255
3 -13 2 255 255 255
4 -13 2 255 255 255
5 -13 2 255 255 255
6 -13 2 159 49 30
7 -13 2 159 49 30
8 -13 2 159 49 30
15 -13 2 215 188 117
-3 -12 2 93 50 19
-2 -12 2 93 50 19
-1 -12 2 93 50 19
0 -12 2 93 50 19
1 -12 2 93 50 19
2 -12 2 93 50 19
3 -12 2 93 50 19
4 -12 2 93 50 19
5 -12 2 93 50 19
6 -12 2 93 50 19
7 -12 2 93 50 19
8 -12 2 93 50 19
9 -12 2 93 50 19
10 -12 2 93 50 19
11 -12 2 93 50 19
12 -12 2 93 50 19
13 -12 2 93 50 19
14 -12 2 93 50 19
15 -12 2 215 188 117
-3 -11 2 93 50 19
-2 -11 2 93 50 19
-1 -11 2 93 50 19
0 -11 2 93 50 19
1 -11 2 93 50 19
2 -11 2 93 50 19
3 -11 2 93 50 19
4 -11 2 93 50 19
5 -11 2 93 50 19
6 -11 2 93 50 19
7 -11 2 93 50 19
8 -11 2 93 50 19
9 -11 2 93 50 19
10 -11 2 93 50 19
11 -11 2 93 50 19
12 -11 2 93 50 19
13 -11 2 93 50 19
14 -11 2 93 50 19
15 -11 2 215 188 117
-3 -10 2 93 50 19
-2 -10 2 93 50 19
-1 -10 2 93 50 19
0 -10 2 93 50 19
1 -10 2 93 50 19
2 -10 2 93 50 19
3 -10 2 93 50 19
4 -10 2 93 50 19
5 -10 2 93 50 19
6 -10 2 93 50 19
7 -10 2 93 50 19
8 -10 2 93 50 19
9 -10 2 93 50 19
10 -10 2 93 50 19
11 -10 2 93 50 19
12 -10 2 93 50 19
13 -10 2 93 50 19
14 -10 2 93 50 19
15 -10 2 215 188 117
-3 -9 2 93 50 19
-2 -9 2 93 50 19
-1 -9 2 93 50 19
0 -9 2 93 50 19
1 -9 2 93 50 19
2 -9 2 93 50 19
3 -9 2 93 50 19
4 -9 2 93 50 19
5 -9 2 93 50 19
6 -9 2 93 50 19
7 -9 2 93 50 19
8 -9 2 93 50 19
9 -9 2 93 50 19
10 -9 2 93 50 19
11 -9 2 93 50 19
12 -9 2 93 50 19
13 -9 2 93 50 19
14 -9 2 93 50 19
15 -9 2 215 188 117
-3 -8 2 93 50 19
-2 -8 2 93 50 19
-1 -8 2 93 50 19
0 -8 2 93 50 19
1 -8 2 93 50 19
2 -8 2 93 50 19
3 -8 2 93 50 19
4 -8 2 93 50 19
5 -8 2 93 50 19
6 -8 2 93 50 19
7 -8 2 93 50 19
8 -8 2 93 50 19
9 -8 2 93 50 19
10 -8 2 93 50 19
11 -8 2 93 50 19
12 -8 2 93 50 19
13 -8 2 93 50 19
14 -8 2 93 50 19
15 -8 2 215 188 117
-3 -7 2 93 50 19
-2 -7 2 93 50 19
-1 -7 2 93 50 19
0 -7 2 93 50 19
1 -7 2 93 50 19
2 -7 2 93 50 19
3 -7 2 93 50 19
4 -7 2 93 50 19
5 -7 2 93 50 19
6 -7 2 93 50 19
7 -7 2 93 50 19
8 -7 2 93 50 19
9 -7 2 93 50 19
10 -7 2 93 50 19
11 -7 2 93 50 19
12 -7 2 93 50 19
13 -7 2 93 50 19
14 -7 2 93 50 19
15 -7 2 215 188 117
-3 -6 2 93 50 19
-2 -6 2 93 50 19
-1 -6 2 93 50 19
0 -6 2 93 50 19
1 -6 2 93 50 19
2 -6 2 93 50 19
3 -6 2 93 50 19
4 -6 2 93 50 19
5 -6 2 93 50 19
6 -6 2 93 50 19
7 -6 2 93 50 19
8 -6 2 93 50 19
9 -6 2 93 50 19
10 -6 2 93 50 19
11 -6 2 93 50 19
12 -6 2 93 50 19
13 -6 2 93 50 19
14 -6 2 93 50 19
15 -6 2 215 188 117
-3 -5 2 93 50 19
-2 -5 2 93 50 19
-1 -5 2 93 50 19
0 -5 2 93 50 19
1 -5 2 93 50 19
2 -5 2 93 50 19
3 -5 2 93 50 19
4 -5 2 93 50 19
5 -5 2 93 50 19
6 -5 2 93 50 19
7 -5 2 93 50 19
8 -5 2 93 50 19
9 -5 2 93 50 19
10 -5 2 93 50 19
11 -5 2 93 50 19
12 -5 2 93 50 19
13 -5 2 93 50 19
14 -5 2 93 50 19
15 -5 2 215 188 117
-3 -4 2 93 50 19
-2 -4 2 93 50 19
-1 -4 2 93 50 19
0 -4 2 93 50 19
1 -4 2 93 50 19
2 -4 2 93 50 19
3 -4 2 93 50 19
4 -4 2 93 50 19
5 -4 2 93 50 19
6 -4 2 93 50 19
7 -4 2 93 50 19
8 -4 2 93 50 19
9 -4 2 93 50 19
10 -4 2 93 50 19
11 -4 2 93 50 19
12 -4 2 93 50 19
13 -4 2 93 50 19
14 -4 2 93 50 19
15 -4 2 215 188 117
-3 -3 2 93 50 19
-2 -3 2 93 50 19
-1 -3 2 93 50 19
0 -3 2 93 50 19
1 -3 2 93 50 19
2 -3 2 93 50 19
3 -3 2 93 50 19
4 -3 2 93 50 19
5 -3 2 93 50 19
6 -3 2 93 50 19
7 -3 2 93 50 19
8 -3 2 93 50 19
9 -3 2 93 50 19
10 -3 2 93 50 19
11 -3 2 93 50 19
12 -3 2 93 50 19
13 -3 2 93 50 19
14 -3 2 93 50 19
15 -3 2 215 188 117
-3 -2 2 93 50 19
-2 -2 2 93 50 19
-1 -2 2 93 50 19
0 -2 2 93 50 19
1 -2 2 93 50 19
2 -2 2 93 50 19
3 -2 2 93 50 19
4 -2 2 93 50 19
5 -2 2 93 50 19
6 -2 2 93 50 19
7 -2 2 93 50 19
8 -2 2 93 50 19
9 -2 2 93 50 19
10 -2 2 93 50 19
11 -2 2 93 50 19
12 -2 2 93 50 19
13 -2 2 93 50 19
14 -2 2 93 50 19
15 -2 2 215 188 117
-3 -1 2 93 50 19
-2 -1 2 93 50 19
-1 -1 2 93 50 19
0 -1 2 93 50 19
1 -1 2 93 50 19
2 -1 2 93 50 19
3 -1 2 93 50 19
4 -1 2 93 50 19
5 -1 2 93 50 19
6 -1 2 93 50 19
7 -1 2 93 50 19
8 -1 2 93 50 19
9 -1 2 93 50 19
10 -1 2 93 50 19
11 -1 2 93 50 19
12 -1 2 93 50 19
13 -1 2 93 50 19
14 -1 2 93 50 19
15 -1 2 215 188 117
-3 0 2 93 50 19
-2 0 2 93 50 19
-1 0 2 93 50 19
0 0 2 93 50 19
1 0 2 93 50 19
2 0 2 93 50 19
3 0 2 93 50 19
4 0 2 93 50 19
5 0 2 93 50 19
6 0 2 93 50 19
7 0 2 93 50 19
8 0 2 93 50 19
9 0 2 93 50 19
10 0 2 93 50 19
11 0 2 93 50 19
12 0 2 93 50 19
13 0 2 93 50 19
14 0 2 93 50 19
15 0 2 215 188 117
2 1 2 255 255 255
3 1 2 255 255 255
4 1 2 159 49 30
5 1 2 192 142 56
6 1 2 159 49 30
9 1 2 255 255 255
10 1 2 255 255 255
11 1 2 255 255 255
12 1 2 255 255 255
13 1 2 255 255 255
14 1 2 93 50 19
15 1 2 215 188 117
14 2 2 93 50 19
15 2 2 215 188 117
15 3 2 215 188 117
15 4 2 215 188 117
15 5 2 215 188 117
15 6 2 215 188 117
15 7 2 215 188 117
-13 8 2 70 147 25
-12 8 2 70 147 25
-11 8 2 70 147 25
-10 8 2 70 147 25
-9 8 2 70 147 25
-8 8 2 70 147 25
-7 8 2 70 147 25
15 8 2 215 188 117
-13 9 2 70 147 25
-12 9 2 70 147 25
-11 9 2 70 147 25
-10 9 2 70 147 25
-9 9 2 70 147 25
-8 9 2 70 147 25
-7 9 2 70 147 25
15 9 2 215 188 117
-13 10 2 70 147 25
-12 10 2 70 147 25
-11 10 2 70 147 25
-10 10 2 70 147 25
-9 10 2 70 147 25
-8 10 2 70 147 25
-7 10 2 70 147 25
1 10 2 121 63 25
2 10 2 121 63 25
3 10 2 121 63 25
4 10 2 121 63 25
5 10 2 121 63 25
6 10 2 121 63 25
7 10 2 121 63 25
8 10 2 121 63 25
9 10 2 121 63 25
10 10 2 121 63 25
11 10 2 121 63 25
15 10 2 215 188 117
-13 11 2 70 147 25
-12 11 2 70 147 25
-11 11 2 70 147 25
-10 11 2 70 147 25
-9 11 2 70 147 25
-8 11 2 70 147 25
-7 11 2 70 147 25
1 11 2 121 63 25
2 11 2 93 50 19
3 11 2 93 50 19
4 11 2 93 50 19
5 11 2 93 50 19
6 11 2 93 50 19
7 11 2 93 50 19
8 11 2 93 50 19
9 11 2 93 50 19
10 11 2 93 50 19
11 11 2 121 63 25
15 11 2 215 188 117
-13 12 2 70 147 25
-12 12 2 70 147 25
-11 12 2 70 147 25
-10 12 2 70 147 25
-9 12 2 70 147 25
-8 12 2 70 147 25
-7 12 2 70 147 25
1 12 2 121 63 25
2 12 2 93 50 19
3 12 2 93 50 19
4 12 2 93 50 19
5 12 2 93 50 19
6 12 2 93 50 19
7 12 2 93 50 19
8 12 2 93 50 19
9 12 2 93 50 19
10 12 2 93 50 19
11 12 2 121 63 25
15 12 2 215 188 117
-13 13 2 70 147 25
-12 13 2 70 147 25
-11 13 2 70 147 25
-10 13 2 70 147 25
-9 13 2 70 147 25
-8 13 2 70 147 25
-7 13 2 70 147 25
1 13 2 121 63 25
2 13 2 93 50 19
3 13 2 93 50 19
4 13 2 93 50 19
5 13 2 93 50 19
6 13 2 93 50 19
7 13 2 93 50 19
8 13 2 93 50 19
9 13 2 93 50 19
10 13 2 93 50 19
11 13 2 121 63 25
15 13 2 215 188 117
-13 14 2 70 147 25
-12 14 2 70 147 25
-11 14 2 70 147 25
-10 14 2 70 147 25
-9 14 2 70 147 25
-8 14 2 70 147 25
-7 14 2 70 147 25
1 14 2 121 63 25
2 14 2 93 50 19
3 14 2 93 50 19
4 14 2 93 50 19
5 14 2 93 50 19
6 14 2 93 50 19
7 14 2 93 50 19
8 14 2 93 50 19
9 14 2 93 50 19
10 14 2 93 50 19
11 14 2 121 63 25
15 14 2 215 188 117
-16 15 2 136 83 31
-15 15 2 215 188 117
-14 15 2 215 188 117
-13 15 2 215 188 117
-12 15 2 215 188 117
-11 15 2 215 188 117
-10 15 2 215 188 117
-9 15 2 215 188 117
-8 15 2 215 188 117
-7 15 2 215 188 117
-6 15 2 215 188 117
-5 15 2 215 188 117
-4 15 2 215 188 117
-3 15 2 215 188 117
-2 15 2 215 188 117
-1 15 2 215 188 117
0 15 2 215 188 117
1 15 2 215 188 117
2 15 2 215 188 117
3 15 2 215 188 117
4 15 2 215 188 117
5 15 2 215 188 117
6 15 2 215 188 117
7 15 2 215 188 117
8 15 2 215 188 117
9 15 2 215 188 117
10 15 2 215 188 117
11 15 2 215 188 117
12 15 2 215 188 117
13 15 2 215 188 117
14 15 2 215 188 117
15 15 2 215 188 117
15 -16 3 136 83 31
15 -15 3 215 188 117
14 -14 3 93 50 19
15 -14 3 215 188 117
-2 -13 3 255 255 255
-1 -13 3 255 255 255
0 -13 3 255 255 255
1 -13 3 255 255 255
2 -13 3 255 255 255
3 -13 3 255 255 255
4 -13 3 255 255 255
5 -13 3 159 49 30
6 -13 3 159 49 30
7 -13 3 159 49 30
8 -13 3 192 142 56
9 -13 3 255 255 255
10 -13 3 255 255 255
11 -13 3 255 255 255
12 -13 3 255 255 255
13 -13 3 255 255 255
14 -13 3 255 255 255
15 -13 3 215 188 117
-3 -12 3 255 255 255
-2 -12 3 255 255 255
-1 -12 3 255 255 255
0 -12 3 255 255 255
1 -12 3 255 255 255
2 -12 3 255 255 255
3 -12 3 255 255 255
4 -12 3 255 255 255
5 -12 3 255 255 255
6 -12 3 255 255 255
7 -12 3 255 255 255
8 -12 3 255 255 255
9 -12 3 255 255 255
10 -12 3 255 255 255
11 -12 3 255 255 255
12 -12 3 255 255 255
13 -12 3 255 255 255
14 -12 3 255 255 255
15 -12 3 215 188 117
-3 -11 3 255 255 255
-2 -11 3 255 255 255
-1 -11 3 255 255 255
0 -11 3 255 255 255
1 -11 3 255 255 255
2 -11 3 255 255 255
3 -11 3 255 255 255
4 -11 3 255 255 255
5 -11 3 255 255 255
6 -11 3 255 255 255
7 -11 3 255 255 255
8 -11 3 255 255 255
9 -11 3 255 255 255
10 -11 3 255 255 255
11 -11 3 255 255 255
12 -11 3 255 255 255
13 -11 3 255 255 255
14 -11 3 255 255 255
15 -11 3 215 188 117
-3 -10 3 255 255 255
-2 -10 3 255 255 255
-1 -10 3 255 255 255
0 -10 3 255 255 255
1 -10 3 255 255 255
2 -10 3 255 255 255
3 -10 3 255 255 255
4 -10 3 255 255 255
5 -10 3 255 255 255
6 -10 3 255 255 255
7 -10 3 255 255 255
8 -10 3 255 255 255
9 -10 3 255 255 255
10 -10 3 255 255 255
11 -10 3 255 255 255
12 -10 3 255 255 255
13 -10 3 255 255 255
14 -10 3 255 255 255
15 -10 3 215 188 117
-3 -9 3 255 255 255
-2 -9 3 255 255 255
-1 -9 3 255 255 255
0 -9 3 255 255 255
1 -9 3 255 255 255
2 -9 3 255 255 255
3 -9 3 255 255 255
4 -9 3 255 255 255
5 -9 3 255 255 255
6 -9 3 255 255 255
7 -9 3 255 255 255
8 -9 3 255 255 255
9 -9 3 255 255 255
10 -9 3 255 255 255
11 -9 3 255 255 255
12 -9 3 255 255 255
13 -9 3 255 255 255
14 -9 3 255 255 255
15 -9 3 215 188 117
-3 -8 3 255 255 255
-2 -8 3 255 255 255
-1 -8 3 255 255 255
0 -8 3 255 255 255
1 -8 3 255 255 255
2 -8 3 255 255 255
3 -8 3 255 255 255
4 -8 3 255 255 255
5 -8 3 255 255 255
6 -8 3 255 255 255
7 -8 3 255 255 255
8 -8 3 255 255 255
9 -8 3 255 255 255
10 -8 3 255 255 255
11 -8 3 255 255 255
12 -8 3 255 255 255
13 -8 3 255 255 255
14 -8 3 255 255 255
15 -8 3 215 188 117
-3 -7 3 255 255 255
-2 -7 3 255 255 255
-1 -7 3 255 255 255
0 -7 3 255 255 255
1 -7 3 255 255 255
2 -7 3 255 255 255
3 -7 3 255 255 255
4 -7 3 255 255 255
5 -7 3 255 255 255
6 -7 3 255 255 255
7 -7 3 255 255 255
8 -7 3 255 255 255
9 -7 3 255 255 255
10 -7 3 255 255 255
11 -7 3 255 255 255
12 -7 3 255 255 255
13 -7 3 255 255 255
14 -7 3 255 255 255
15 -7 3 215 188 117
-3 -6 3 255 255 255
-2 -6 3 255 255 255
-1 -6 3 255 255 255
0 -6 3 255 255 255
1 -6 3 255 255 255
2 -6 3 255 255 255
3 -6 3 255 255 255
4 -6 3 255 255 255
5 -6 3 255 255 255
6 -6 3 255 255 255
7 -6 3 255 255 255
8 -6 3 255 255 255
9 -6 3 255 255 255
10 -6 3 255 255 255
11 -6 3 255 255 255
12 -6 3 255 255 255
13 -6 3 255 255 255
14 -6 3 255 255 255
15 -6 3 215 188 117
-3 -5 3 255 255 255
-2 -5 3 255 255 255
-1 -5 3 255 255 255
0 -5 3 255 255 255
1 -5 3 255 255 255
2 -5 3 255 255 255
3 -5 3 255 255 255
4 -5 3 255 255 255
5 -5 3 255 255 255
6 -5 3 255 255 255
7 -5 3 255 255 255
8 -5 3 255 255 255
9 -5 3 255 255 255
10 -5 3 255 255 255
11 -5 3 255 255 255
12 -5 3 255 255 255
13 -5 3 255 255 255
14 -5 3 255 255 255
15 -5 3 215 188 117
-3 -4 3 255 255 255
-2 -4 3 255 255 255
-1 -4 3 255 255 255
0 -4 3 255 255 255
1 -4 3 255 255 255
2 -4 3 255 255 255
3 -4 3 255 255 255
4 -4 3 255 255 255
5 -4 3 255 255 255
6 -4 3 255 255 255
7 -4 3 255 255 255
8 -4 3 255 255 255
9 -4 3 255 255 255
10 -4 3 255 255 255
11 -4 3 255 255 255
12 -4 3 255 255 255
13 -4 3 255 255 255
14 -4 3 255 255 255
15 -4 3 215 188 117
-3 -3 3 255 255 255
-2 -3 3 255 255 255
-1 -3 3 255 255 255
0 -3 3 255 255 255
1 -3 3 255 255 255
2 -3 3 255 255 255
3 -3 3 255 255 255
4 -3 3 255 255 255
5 -3 3 255 255 255
6 -3 3 255 255 255
7 -3 3 255 255 255
8 -3 3 255 255 255
9 -3 3 255 255 255
10 -3 3 255 255 255
11 -3 3 255 255 255
12 -3 3 255 255 255
13 -3 3 255 255 255
14 -3 3 255 255 255
15 -3 3 215 188 117
-3 -2 3 255 255 255
-2 -2 3 255 255 255
-1 -2 3 255 255 255
0 -2 3 255 255 255
1 -2 3 255 255 255
2 -2 3 255 255 255
3 -2 3 255 255 255
4 -2 3 255 255 255
5 -2 3 255 255 255
6 -2 3 255 255 255
7 -2 3 255 255 255
8 -2 3 255 255 255
9 -2 3 255 255 255
10 -2 3 255 255 255
11 -2 3 255 255 255
12 -2 3 255 255 255
13 -2 3 255 255 255
14 -2 3 255 255 255
15 -2 3 215 188 117
-3 -1 3 255 255 255
-2 -1 3 255 255 255
-1 -1 3 255 255 255
0 -1 3 255 255 255
1 -1 3 255 255 255
2 -1 3 255 255 255
3 -1 3 255 255 255
4 -1 3 255 255 255
5 -1 3 255 255 255
6 -1 3 255 255 255
7 -1 3 255 255 255
8 -1 3 255 255 255
9 -1 3 255 255 255
10 -1 3 255 255 255
11 -1 3 255 255 255
12 -1 3 255 255 255
13 -1 3 255 255 255
14 -1 3 255 255 255
15 -1 3 215 188 117
-3 0 3 255 255 255
-2 0 3 255 255 255
-1 0 3 255 255 255
0 0 3 255 255 255
1 0 3 255 255 255
2 0 3 255 255 255
3 0 3 255 255 255
4 0 3 255 255 255
5 0 3 255 255 255
6 0 3 255 255 255
7 0 3 255 255 255
8 0 3 255 255 255
9 0 3 255 255 255
10 0 3 255 255 255
11 0 3 255 255 255
12 0 3 255 255 255
13 0 3 255 255 255
14 0 3 255 255 255
15 0 3 215 188 117
-2 1 3 255 255 255
-1 1 3 255 255 255
0 1 3 255 255 255
1 1 3 255 255 255
2 1 3 255 255 255
3 1 3 255 255 255
4 1 3 159 49 30
5 1 3 192 142 56
6 1 3 159 49 30
7 1 3 159 49 30
8 1 3 255 255 255
9 1 3 255 255 255
10 1 3 255 255 255
11 1 3 255 255 255
12 1 3 255 255 255
13 1 3 255 255 255
14 1 3 255 255 255
15 1 3 215 188 117
14 2 3 93 50 19
15 2 3 215 188 117
15 3 3 215 188 117
15 4 3 215 188 117
15 5 3 215 188 117
15 6 3 215 188 117
15 7 3 215 188 117
-13 8 3 70 147 25
-12 8 3 70 147 25
-11 8 3 70 147 25
-10 8 3 70 147 25
-9 8 3 70 147 25
-8 8 3 70 147 25
-7 8 3 70 147 25
15 8 3 215 188 117
-13 9 3 70 147 25
-12 9 3 70 147 25
-11 9 3 70 147 25
-10 9 3 70 147 25
-9 9 3 70 147 25
-8 9 3 70 147 25
-7 9 3 70 147 25
2 9 3 93 50 19
3 9 3 93 50 19
4 9 3 93 50 19
5 9 3 93 50 19
6 9 3 82 44 17
7 9 3 93 50 19
8 9 3 93 50 19
9 9 3 93 50 19
10 9 3 93 50 19
15 9 3 215 188 117
-13 10 3 70 147 25
-12 10 3 70 147 25
-11 10 3 70 147 25
-10 10 3 70 147 25
-9 10 3 70 147 25
-8 10 3 70 147 25
-7 10 3 70 147 25
1 10 3 121 63 25
2 10 3 93 50 19
3 10 3 93 50 19
4 10 3 93 50 19
5 10 3 93 50 19
6 10 3 93 50 19
7 10 3 93 50 19
8 10 3 93 50 19
9 10 3 93 50 19
10 10 3 93 50 19
11 10 3 121 63 25
15 10 3 215 188 117
-13 11 3 70 147 25
-12 11 3 70 147 25
-11 11 3 70 147 25
-10 11 3 70 147 25
-9 11 3 70 147 25
-8 11 3 70 147 25
-7 11 3 70 147 25
1 11 3 121 63 25
2 11 3 93 50 19
3 11 3 93 50 19
4 11 3 93 50 19
5 11 3 93 50 19
6 11 3 93 50 19
7 11 3 93 50 19
8 11 3 93 50 19
9 11 3 93 50 19
10 11 3 93 50 19
11 11 3 121 63 25
15 11 3 215 188 117
-13 12 3 70 147 25
-12 12 3 70 147 25
-11 12 3 70 147 25
-10 12 3 70 147 25
-9 12 3 70 147 25
-8 12 3 70 147 25
-7 12 3 70 147 25
1 12 3 121 63 25
2 12 3 93 50 19
3 12 3 93 50 19
4 12 3 93 50 19
5 12 3 93 50 19
6 12 3 93 50 19
7 12 3 93 50 19
8 12 3 93 50 19
9 12 3 93 50 19
10 12 3 93 50 19
11 12 3 121 63 25
15 12 3 215 188 117
-13 13 3 70 147 25
-12 13 3 70 147 25
-11 13 3 70 147 25
-10 13 3 70 147 25
-9 13 3 70 147 25
-8 13 3 70 147 25
-7 13 3 70 147 25
1 13 3 121 63 25
2 13 3 93 50 19
3 13 3 93 50 19
4 13 3 93 50 19
5 13 3 93 50 19
6 13 3 93 50 19
7 13 3 93 50 19
8 13 3 93 50 19
9 13 3 93 50 19
10 13 3 93 50 19
11 13 3 121 63 25
15 13 3 215 188 117
-13 14 3 70 147 25
-12 14 3 70 147 25
-11 14 3 70 147 25
-10 14 3 70 147 25
-9 14 3 70 147 25
-8 14 3 70 147 25
-7 14 3 70 147 25
1 14 3 121 63 25
2 14 3 93 50 19
3 14 3 93 50 19
4 14 3 93 50 19
5 14 3 93 50 19
6 14 3 93 50 19
7 14 3 93 50 19
8 14 3 93 50 19
9 14 3 93 50 19
10 14 3 93 50 19
11 14 3 121 63 25
15 14 3 215 188 117
-16 15 3 136 83 31
-15 15 3 215 188 117
-14 15 3 215 188 117
-13 15 3 215 188 117
-12 15 3 215 188 117
-11 15 3 215 188 117
-10 15 3 215 188 117
-9 15 3 215 188 117
-8 15 3 215 188 117
-7 15 3 215 188 117
-6 15 3 215 188 117
-5 15 3 215 188 117
-4 15 3 215 188 117
-3 15 3 215 188 117
-2 15 3 215 188 117
-1 15 3 215 188 117
0 15 3 215 188 117
1 15 3 215 188 117
2 15 3 215 188 117
3 15 3 215 188 117
4 15 3 215 188 117
5 15 3 215 188 117
6 15 3 215 188 117
7 15 3 215 188 117
8 15 3 215 188 117
9 15 3 215 188 117
10 15 3 215 188 117
11 15 3 215 188 117
12 15 3 215 188 117
13 15 3 215 188 117
14 15 3 215 188 117
15 15 3 215 188 117
15 -16 4 136 83 31
15 -15 4 215 188 117
14 -14 4 93 50 19
15 -14 4 215 188 117
-2 -13 4 255 255 255
-1 -13 4 255 255 255
0 -13 4 255 255 255
1 -13 4 255 255 255
2 -13 4 255 255 255
3 -13 4 255 255 255
4 -13 4 159 49 30
5 -13 4 159 49 30
6 -13 4 159 49 30
7 -13 4 159 49 30
8 -13 4 192 142 56
9 -13 4 255 255 255
10 -13 4 255 255 255
11 -13 4 255 255 255
12 -13 4 255 255 255
13 -13 4 255 255 255
14 -13 4 255 255 255
15 -13 4 215 188 117
-3 -12 4 255 255 255
-2 -12 4 255 255 255
-1 -12 4 255 255 255
0 -12 4 255 255 255
1 -12 4 255 255 255
2 -12 4 255 255 255
3 -12 4 255 255 255
4 -12 4 255 255 255
5 -12 4 255 255 255
6 -12 4 255 255 255
7 -12 4 255 255 255
8 -12 4 255 255 255
9 -12 4 255 255 255
10 -12 4 255 255 255
11 -12 4 255 255 255
12 -12 4 255 255 255
13 -12 4 255 255 255
14 -12 4 255 255 255
15 -12 4 215 188 117
-3 -11 4 255 255 255
-2 -11 4 255 255 255
-1 -11 4 255 255 255
0 -11 4 255 255 255
1 -11 4 255 255 255
2 -11 4 255 255 255
3 -11 4 255 255 255
4 -11 4 255 255 255
5 -11 4 255 255 255
6 -11 4 255 255 255
7 -11 4 255 255 255
8 -11 4 255 255 255
9 -11 4 255 255 255
10 -11 4 255 255 255
11 -11 4 255 255 255
12 -11 4 255 255 255
13 -11 4 255 255 255
14 -11 4 255 255 255
15 -11 4 215 188 117
-3 -10 4 255 255 255
-2 -10 4 255 255 255
-1 -10 4 255 255 255
0 -10 4 255 255 255
1 -10 4 255 255 255
2 -10 4 255 255 255
3 -10 4 255 255 255
4 -10 4 255 255 255
5 -10 4 255 255 255
6 -10 4 255 255 255
7 -10 4 255 255 255
8 -10 4 255 255 255
9 -10 4 255 255 255
10 -10 4 255 255 255
11 -10 4 255 255 255
12 -10 4 255 255 255
13 -10 4 255 255 255
14 -10 4 255 255 255
15 -10 4 215 188 117
-3 -9 4 255 255 255
-2 -9 4 255 255 255
-1 -9 4 255 255 255
0 -9 4 255 255 255
1 -9 4 255 255 255
2 -9 4 255 255 255
3 -9 4 255 255 255
4 -9 4 255 255 255
5 -9 4 255 255 255
6 -9 4 255 255 255
7 -9 4 255 255 255
8 -9 4 255 255 255
9 -9 4 255 255 255
10 -9 4 255 255 255
11 -9 4 255 255 255
12 -9 4 255 255 255
13 -9 4 255 255 255
14 -9 4 255 255 255
15 -9 4 215 188 117
-3 -8 4 255 255 255
-2 -8 4 255 255 255
-1 -8 4 255 255 255
0 -8 4 255 255 255
1 -8 4 255 255 255
2 -8 4 255 255 255
3 -8 4 255 255 255
4 -8 4 255 255 255
5 -8 4 255 255 255
6 -8 4 255 255 255
7 -8 4 255 255 255
8 -8 4 255 255 255
9 -8 4 255 255 255
10 -8 4 255 255 255
11 -8 4 255 255 255
12 -8 4 255 255 255
13 -8 4 255 255 255
14 -8 4 255 255 255
15 -8 4 215 188 117
-3 -7 4 255 255 255
-2 -7 4 255 255 255
-1 -7 4 255 255 255
0 -7 4 255 255 255
1 -7 4 255 255 255
2 -7 4 255 255 255
3 -7 4 255 255 255
4 -7 4 255 255 255
5 -7 4 255 255 255
6 -7 4 255 255 255
7 -7 4 255 255 255
8 -7 4 255 255 255
9 -7 4 255 255 255
10 -7 4 255 255 255
11 -7 4 255 255 255
12 -7 4 255 255 255
13 -7 4 255 255 255
14 -7 4 255 255 255
15 -7 4 215 188 117
-3 -6 4 255 255 255
-2 -6 4 255 255 255
-1 -6 4 255 255 255
0 -6 4 255 255 255
1 -6 4 255 255 255
2 -6 4 255 255 255
3 -6 4 255 255 255
4 -6 4 255 255 255
5 -6 4 255 255 255
6 -6 4 255 255 255
7 -6 4 255 255 255
8 -6 4 255 255 255
9 -6 4 255 255 255
10 -6 4 255 255 255
11 -6 4 255 255 255
12 -6 4 255 255 255
13 -6 4 255 255 255
14 -6 4 255 255 255
15 -6 4 215 188 117
-3 -5 4 255 255 255
-2 -5 4 255 255 255
-1 -5 4 255 255 255
0 -5 4 255 255 255
1 -5 4 255 255 255
2 -5 4 255 255 255
3 -5 4 255 255 255
4 -5 4 255 255 255
5 -5 4 255 255 255
6 -5 4 255 255 255
7 -5 4 255 255 255
8 -5 4 255 255 255
9 -5 4 255 255 255
10 -5 4 255 255 255
11 -5 4 255 255 255
12 -5 4 255 255 255
13 -5 4 255 255 255
14 -5 4 255 255 255
15 -5 4 215 188 117
-3 -4 4 255 255 255
-2 -4 4 255 255 255
-1 -4 4 255 255 255
0 -4 4 255 255 255
1 -4 4 255 255 255
2 -4 4 255 255 255
3 -4 4 255 255 255
4 -4 4 255 255 255
5 -4 4 255 255 255
6 -4 4 255 255 255
7 -4 4 255 255 255
8 -4 4 255 255 255
9 -4 4 255 255 255
10 -4 4 255 255 255
11 -4 4 255 255 255
12 -4 4 255 255 255
13 -4 4 255 255 255
14 -4 4 255 255 255
15 -4 4 215 188 117
-3 -3 4 255 255 255
-2 -3 4 255 255 255
-1 -3 4 255 255 255
0 -3 4 255 255 255
1 -3 4 255 255 255
2 -3 4 255 255 255
3 -3 4 255 255 255
4 -3 4 255 255 255
5 -3 4 255 255 255
6 -3 4 255 255 255
7 -3 4 255 255 255
8 -3 4 255 255 255
9 -3 4 255 255 255
10 -3 4 255 255 255
11 -3 4 255 255 255
12 -3 4 255 255 255
13 -3 4 255 255 255
14 -3 4 255 255 255
15 -3 4 215 188 117
-3 -2 4 255 255 255
-2 -2 4 255 255 255
-1 -2 4 255 255 255
0 -2 4 255 255 255
1 -2 4 255 255 255
2 -2 4 255 255 255
3 -2 4 255 255 255
4 -2 4 255 255 255
5 -2 4 255 255 255
6 -2 4 255 255 255
7 -2 4 255 255 255
8 -2 4 255 255 255
9 -2 4 255 255 255
10 -2 4 255 255 255
11 -2 4 255 255 255
12 -2 4 255 255 255
13 -2 4 255 255 255
14 -2 4 255 255 255
15 -2 4 215 188 117
-3 -1 4 255 255 255
-2 -1 4 255 255 255
-1 -1 4 255 255 255
0 -1 4 255 255 255
1 -1 4 255 255 255
2 -1 4 255 255 255
3 -1 4 255 255 255
4 -1 4 255 255 255
5 -1 4 255 255 255
6 -1 4 255 255 255
7 -1 4 255 255 255
8 -1 4 255 255 255
9 -1 4 255 255 255
10 -1 4 255 255 255
11 -1 4 255 255 255
12 -1 4 255 255 255
13 -1 4 255 255 255
14 -1 4 255 255 255
15 -1 4 215 188 117
-3 0 4 255 255 255
-2 0 4 255 255 255
-1 0 4 255 255 255
0 0 4 255 255 255
1 0 4 255 255 255
2 0 4 255 255 255
3 0 4 255 255 255
4 0 4 255 255 255
5 0 4 255 255 255
6 0 4 255 255 255
7 0 4 255 255 255
8 0 4 255 255 255
9 0 4 255 255 255
10 0 4 255 255 255
11 0 4 255 255 255
12 0 4 255 255 255
13 0 4 255 255 255
14 0 4 255 255 255
15 0 4 215 188 117
-2 1 4 255 255 255
-1 1 4 255 255 255
0 1 4 255 255 255
1 1 4 255 255 255
2 1 4 255 255 255
3 1 4 255 255 255
4 1 4 159 49 30
5 1 4 159 49 30
6 1 4 192 142 56
7 1 4 159 49 30
8 1 4 159 49 30
9 1 4 255 255 255
10 1 4 255 255 255
11 1 4 255 255 255
12 1 4 255 255 255
13 1 4 255 255 255
14 1 4 255 255 255
15 1 4 215 188 117
14 2 4 93 50 19
15 2 4 215 188 117
15 3 4 215 188 117
15 4 4 215 188 117
15 5 4 215 188 117
15 6 4 215 188 117
15 7 4 215 188 117
-13 8 4 61 129 22
-12 8 4 61 129 22
-11 8 4 61 129 22
-10 8 4 61 129 22
-9 8 4 61 129 22
-8 8 4 61 129 22
-7 8 4 61 129 22
15 8 4 215 188 117
-13 9 4 61 129 22
-12 9 4 61 129 22
-11 9 4 61 129 22
-10 9 4 61 129 22
-9 9 4 61 129 22
-8 9 4 61 129 22
-7 9 4 61 129 22
2 9 4 93 50 19
3 9 4 93 50 19
4 9 4 93 50 19
5 9 4 93 50 19
6 9 4 82 44 17
7 9 4 93 50 19
8 9 4 93 50 19
9 9 4 93 50 19
10 9 4 93 50 19
15 9 4 215 188 117
-13 10 4 61 129 22
-12 10 4 61 129 22
-11 10 4 61 129 22
-10 10 4 61 129 22
-9 10 4 61 129 22
-8 10 4 61 129 22
-7 10 4 61 129 22
1 10 4 121 63 25
2 10 4 93 50 19
3 10 4 93 50 19
4 10 4 93 50 19
5 10 4 93 50 19
6 10 4 93 50 19
7 10 4 93 50 19
8 10 4 93 50 19
9 10 4 93 50 19
10 10 4 93 50 19
11 10 4 121 63 25
15 10 4 215 188 117
-13 11 4 61 129 22
-12 11 4 61 129 22
-11 11 4 61 129 22
-10 11 4 61 129 22
-9 11 4 61 129 22
-8 11 4 61 129 22
-7 11 4 61 129 22
1 11 4 121 63 25
2 11 4 93 50 19
3 11 4 93 50 19
4 11 4 93 50 19
5 11 4 93 50 19
6 11 4 93 50 19
7 11 4 93 50 19
8 11 4 93 50 19
9 11 4 93 50 19
10 11 4 93 50 19
11 11 4 121 63 25
15 11 4 215 188 117
-13 12 4 61 129 22
-12 12 4 61 129 22
-11 12 4 61 129 22
-10 12 4 61 129 22
-9 12 4 61 129 22
-8 12 4 61 129 22
-7 12 4 61 129 22
1 12 4 121 63 25
2 12 4 93 50 19
3 12 4 93 50 19
4 12 4 93 50 19
5 12 4 93 50 19
6 12 4 93 50 19
7 12 4 93 50 19
8 12 4 93 50 19
9 12 4 93 50 19
10 12 4 93 50 19
11 12 4 121 63 25
15 12 4 215 188 117
-13 13 4 70 147 25
-12 13 4 70 147 25
-11 13 4 70 147 25
-10 13 4 70 147 25
-9 13 4 70 147 25
-8 13 4 70 147 25
-7 13 4 70 147 25
1 13 4 121 63 25
2 13 4 93 50 19
3 13 4 93 50 19
4 13 4 93 50 19
5 13 4 93 50 19
6 13 4 93 50 19
7 13 4 93 50 19
8 13 4 93 50 19
9 13 4 93 50 19
10 13 4 93 50 19
11 13 4 121 63 25
15 13 4 215 188 117
-13 14 4 70 147 25
-12 14 4 70 147 25
-11 14 4 70 147 25
-10 14 4 70 147 25
-9 14 4 70 147 25
-8 14 4 70 147 25
-7 14 4 70 147 25
1 14 4 121 63 25
2 14 4 93 50 19
3 14 4 93 50 19
4 14 4 93 50 19
5 14 4 93 50 19
6 14 4 93 50 19
7 14 4 93 50 19
8 14 4 93 50 19
9 14 4 93 50 19
10 14 4 93 50 19
11 14 4 121 63 25
15 14 4 215 188 117
-16 15 4 136 83 31
-15 15 4 215 188 117
-14 15 4 215 188 117
-13 15 4 215 188 117
-12 15 4 215 188 117
-11 15 4 215 188 117
-10 15 4 215 188 117
-9 15 4 215 188 117
-8 15 4 215 188 117
-7 15 4 215 188 117
-6 15 4 215 188 117
-5 15 4 215 188 117
-4 15 4 215 188 117
-3 15 4 215 188 117
-2 15 4 215 188 117
-1 15 4 215 188 117
0 15 4 215 188 117
1 15 4 215 188 117
2 15 4 215 188 117
3 15 4 215 188 117
4 15 4 215 188 117
5 15 4 215 188 117
6 15 4 215 188 117
7 15 4 215 188 117
8 15 4 215 188 117
9 15 4 215 188 117
10 15 4 215 188 117
11 15 4 215 188 117
12 15 4 215 188 117
13 15 4 215 188 117
14 15 4 215 188 117
15 15 4 215 188 117
15 -16 5 136 83 31
15 -15 5 215 188 117
14 -14 5 93 50 19
15 -14 5 215 188 117
-2 -13 5 255 255 255
-1 -13 5 255 255 255
0 -13 5 255 255 255
1 -13 5 255 255 255
2 -13 5 255 255 255
3 -13 5 255 255 255
4 -13 5 159 49 30
5 -13 5 159 49 30
6 -13 5 159 49 30
7 -13 5 192 142 56
8 -13 5 159 49 30
9 -13 5 255 255 255
10 -13 5 255 255 255
11 -13 5 255 255 255
12 -13 5 255 255 255
13 -13 5 255 255 255
14 -13 5 255 255 255
15 -13 5 215 188 117
-3 -12 5 255 255 255
-2 -12 5 255 255 255
-1 -12 5 255 255 255
0 -12 5 255 255 255
1 -12 5 255 255 255
2 -12 5 255 255 255
3 -12 5 255 255 255
4 -12 5 159 49 30
5 -12 5 159 49 30
6 -12 5 159 49 30
7 -12 5 192 142 56
8 -12 5 159 49 30
9 -12 5 255 255 255
10 -12 5 255 255 255
11 -12 5 255 255 255
12 -12 5 255 255 255
13 -12 5 255 255 255
14 -12 5 255 255 255
15 -12 5 215 188 117
-3 -11 5 255 255 255
-2 -11 5 255 255 255
-1 -11 5 255 255 255
0 -11 5 255 255 255
1 -11 5 255 255 255
2 -11 5 255 255 255
3 -11 5 255 255 255
4 -11 5 159 49 30
5 -11 5 159 49 30
6 -11 5 159 49 30
7 -11 5 192 142 56
8 -11 5 159 49 30
9 -11 5 255 255 255
10 -11 5 255 255 255
11 -11 5 255 255 255
12 -11 5 255 255 255
13 -11 5 255 255 255
14 -11 5 255 255 255
15 -11 5 215 188 117
-3 -10 5 255 255 255
-2 -10 5 255 255 255
-1 -10 5 255 255 255
0 -10 5 255 255 255
1 -10 5 255 255 255
2 -10 5 255 255 255
3 -10 5 255 255 255
4 -10 5 159 49 30
5 -10 5 159 49 30
6 -10 5 159 49 30
7 -10 5 192 142 56
8 -10 5 159 49 30
9 -10 5 255 255 255
10 -10 5 255 255 255
11 -10 5 255 255 255
12 -10 5 255 255 255
13 -10 5 255 255 255
14 -10 5 255 255 255
15 -10 5 215 188 117
-3 -9 5 255 255 255
-2 -9 5 255 255 255
-1 -9 5 255 255 255
0 -9 5 255 255 255
1 -9 5 255 255 255
2 -9 5 255 255 255
3 -9 5 255 255 255
4 -9 5 159 49 30
5 -9 5 159 49 30
6 -9 5 159 49 30
7 -9 5 192 142 56
8 -9 5 159 49 30
9 -9 5 255 255 255
10 -9 5 255 255 255
11 -9 5 255 255 255
12 -9 5 255 255 255
13 -9 5 255 255 255
14 -9 5 255 255 255
15 -9 5 215 188 117
-3 -8 5 255 255 255
-2 -8 5 255 255 255
-1 -8 5 255 255 255
0 -8 5 255 255 255
1 -8 5 255 255 255
2 -8 5 255 255 255
3 -8 5 255 255 255
4 -8 5 159 49 30
5 -8 5 159 49 30
6 -8 5 159 49 30
7 -8 5 192 142 56
8 -8 5 159 49 30
9 -8 5 255 255 255
10 -8 5 255 255 255
11 -8 5 255 255 255
12 -8 5 255 255 255
13 -8 5 255 255 255
14 -8 5 255 255 255
15 -8 5 215 188 117
-3 -7 5 255 255 255
-2 -7 5 255 255 255
-1 -7 5 255 255 255
0 -7 5 255 255 255
1 -7 5 255 255 255
2 -7 5 255 255 255
3 -7 5 255 255 255
4 -7 5 159 49 30
5 -7 5 159 49 30
6 -7 5 159 49 30
7 -7 5 192 142 56
8 -7 5 159 49 30
9 -7 5 255 255 255
10 -7 5 255 255 255
11 -7 5 255 255 255
12 -7 5 255 255 255
13 -7 5 255 255 255
14 -7 5 255 255 255
15 -7 5 215 188 117
-3 -6 5 255 255 255
-2 -6 5 255 255 255
-1 -6 5 255 255 255
0 -6 5 255 255 255
1 -6 5 255 255 255
2 -6 5 255 255 255
3 -6 5 255 255 255
4 -6 5 159 49 30
5 -6 5 159 49 30
6 -6 5 159 49 30
7 -6 5 192 142 56
8 -6 5 159 49 30
9 -6 5 255 255 255
10 -6 5 255 255 255
11 -6 5 255 255 255
12 -6 5 255 255 255
13 -6 5 255 255 255
14 -6 5 255 255 255
15 -6 5 215 188 117
-3 -5 5 255 255 255
-2 -5 5 255 255 255
-1 -5 5 255 255 255
0 -5 5 255 255 255
1 -5 5 255 255 255
2 -5 5 255 255 255
3 -5 5 255 255 255
4 -5 5 159 49 30
5 -5 5 159 49 30
6 -5 5 159 49 30
7 -5 5 192 142 56
8 -5 5 159 49 30
9 -5 5 255 255 255
10 -5 5 255 255 255
11 -5 5 255 255 255
12 -5 5 255 255 255
13 -5 5 255 255 255
14 -5 5 255 255 255
15 -5 5 215 188 117
-3 -4 5 255 255 255
-2 -4 5 255 255 255
-1 -4 5 255 255 255
0 -4 5 255 255 255
1 -4 5 255 255 255
2 -4 5 255 255 255
3 -4 5 255 255 255
4 -4 5 159 49 30
5 -4 5 159 49 30
6 -4 5 159 49 30
7 -4 5 192 142 56
8 -4 5 159 49 30
9 -4 5 255 255 255
10 -4 5 255 255 255
11 -4 5 255 255 255
12 -4 5 255 255 255
13 -4 5 255 255 255
14 -4 5 255 255 255
15 -4 5 215 188 117
-3 -3 5 255 255 255
-2 -3 5 255 255 255
-1 -3 5 255 255 255
0 -3 5 255 255 255
1 -3 5 255 255 255
2 -3 5 255 255 255
3 -3 5 255 255 255
4 -3 5 159 49 30
5 -3 5 159 49 30
6 -3 5 159 49 30
7 -3 5 192 142 56
8 -3 5 159 49 30
9 -3 5 255 255 255
10 -3 5 255 255 255
11 -3 5 255 255 255
12 -3 5 255 255 255
13 -3 5 255 255 255
14 -3 5 255 255 255
15 -3 5 215 188 117
-3 -2 5 255 255 255
-2 -2 5 255 255 255
-1 -2 5 255 255 255
0 -2 5 255 255 255
1 -2 5 255 255 255
2 -2 5 255 255 255
3 -2 5 255 255 255
4 -2 5 159 49 30
5 -2 5 159 49 30
6 -2 5 159 49 30
7 -2 5 192 142 56
8 -2 5 159 49 30
9 -2 5 255 255 255
10 -2 5 255 255 255
11 -2 5 255 255 255
12 -2 5 255 255 255
13 -2 5 255 255 255
14 -2 5 255 255 255
15 -2 5 215 188 117
-3 -1 5 255 255 255
-2 -1 5 255 255 255
-1 -1 5 255 255 255
0 -1 5 255 255 255
1 -1 5 255 255 255
2 -1 5 255 255 255
3 -1 5 255 255 255
4 -1 5 159 49 30
5 -1 5 159 49 30
6 -1 5 159 49 30
7 -1 5 192 142 56
8 -1 5 159 49 30
9 -1 5 255 255 255
10 -1 5 255 255 255
11 -1 5 255 255 255
12 -1 5 255 255 255
13 -1 5 255 255 255
14 -1 5 255 255 255
15 -1 5 215 188 117
-2 0 5 255 255 255
-1 0 5 255 255 255
0 0 5 255 255 255
1 0 5 255 255 255
2 0 5 255 255 255
3 0 5 255 255 255
4 0 5 159 49 30
5 0 5 159 49 30
6 0 5 159 49 30
7 0 5 192 142 56
8 0 5 159 49 30
9 0 5 255 255 255
10 0 5 255 255 255
11 0 5 255 255 255
12 0 5 255 255 255
13 0 5 255 255 255
14 0 5 255 255 255
15 0 5 215 188 117
-2 1 5 255 255 255
-1 1 5 255 255 255
0 1 5 255 255 255
1 1 5 255 255 255
2 1 5 255 255 255
3 1 5 255 255 255
4 1 5 159 49 30
5 1 5 159 49 30
6 1 5 159 49 30
7 1 5 192 142 56
8 1 5 159 49 30
9 1 5 255 255 255
10 1 5 255 255 255
11 1 5 255 255 255
12 1 5 255 255 255
13 1 5 255 255 255
14 1 5 255 255 255
15 1 5 215 188 117
14 2 5 93 50 19
15 2 5 215 188 117
15 3 5 215 188 117
15 4 5 215 188 117
15 5 5 215 188 117
15 6 5 215 188 117
15 7 5 215 188 117
15 8 5 215 188 117
2 9 5 93 50 19
3 9 5 93 50 19
4 9 5 93 50 19
5 9 5 93 50 19
6 9 5 82 44 17
7 9 5 93 50 19
8 9 5 93 50 19
9 9 5 93 50 19
10 9 5 93 50 19
15 9 5 215 188 117
1 10 5 121 63 25
2 10 5 93 50 19
3 10 5 93 50 19
4 10 5 93 50 19
5 10 5 93 50 19
6 10 5 93 50 19
7 10 5 93 50 19
8 10 5 93 50 19
9 10 5 93 50 19
10 10 5 93 50 19
11 10 5 121 63 25
15 10 5 215 188 117
1 11 5 121 63 25
2 11 5 93 50 19
3 11 5 93 50 19
4 11 5 93 50 19
5 11 5 93 50 19
6 11 5 93 50 19
7 11 5 93 50 19
8 11 5 93 50 19
9 11 5 93 50 19
10 11 5 93 50 19
11 11 5 121 63 25
15 11 5 215 188 117
1 12 5 121 63 25
2 12 5 93 50 19
3 12 5 93 50 19
4 12 5 93 50 19
5 12 5 93 50 19
6 12 5 93 50 19
7 12 5 93 50 19
8 12 5 93 50 19
9 12 5 93 50 19
10 12 5 93 50 19
11 12 5 121 63 25
15 12 5 215 188 117
-13 13 5 70 147 25
-12 13 5 70 147 25
-11 13 5 70 147 25
-10 13 5 70 147 25
-9 13 5 70 147 25
-8 13 5 70 147 25
-7 13 5 70 147 25
1 13 5 121 63 25
2 13 5 93 50 19
3 13 5 93 50 19
4 13 5 93 50 19
5 13 5 93 50 19
6 13 5 93 50 19
7 13 5 93 50 19
8 13 5 93 50 19
9 13 5 93 50 19
10 13 5 93 50 19
11 13 5 121 63 25
15 13 5 215 188 117
-13 14 5 70 147 25
-12 14 5 70 147 25
-11 14 5 70 147 25
-10 14 5 70 147 25
-9 14 5 70 147 25
-8 14 5 70 147 25
-7 14 5 70 147 25
1 14 5 121 63 25
2 14 5 93 50 19
3 14 5 93 50 19
4 14 5 93 50 19
5 14 5 93 50 19
6 14 5 93 50 19
7 14 5 93 50 19
8 14 5 93 50 19
9 14 5 93 50 19
10 14 5 93 50 19
11 14 5 121 63 25
15 14 5 215 188 117
-16 15 5 136 83 31
-15 15 5 215 188 117
-14 15 5 215 188 117
-13 15 5 215 188 117
-12 15 5 215 188 117
-11 15 5 215 188 117
-10 15 5 215 188 117
-9 15 5 215 188 117
-8 15 5 215 188 117
-7 15 5 215 188 117
-6 15 5 215 188 117
-5 15 5 215 188 117
-4 15 5 215 188 117
-3 15 5 215 188 117
-2 15 5 215 188 117
-1 15 5 215 188 117
0 15 5 215 188 117
1 15 5 215 188 117
2 15 5 215 188 117
3 15 5 215 188 117
4 15 5 215 188 117
5 15 5 215 188 117
6 15 5 215 188 117
7 15 5 215 188 117
8 15 5 215 188 117
9 15 5 215 188 117
10 15 5 215 188 117
11 15 5 215 188 117
12 15 5 215 188 117
13 15 5 215 188 117
14 15 5 215 188 117
15 15 5 215 188 117
15 -16 6 136 83 31
15 -15 6 215 188 117
14 -14 6 93 50 19
15 -14 6 215 188 117
14 -13 6 93 50 19
15 -13 6 215 188 117
11 -12 6 224 224 222
12 -12 6 224 224 222
13 -12 6 224 224 222
14 -12 6 93 50 19
15 -12 6 215 188 117
10 -11 6 224 224 222
11 -11 6 224 224 222
12 -11 6 224 224 222
13 -11 6 224 224 222
14 -11 6 93 50 19
15 -11 6 215 188 117
10 -10 6 224 224 222
11 -10 6 224 224 222
12 -10 6 224 224 222
13 -10 6 224 224 222
14 -10 6 93 50 19
15 -10 6 215 188 117
10 -9 6 224 224 222
11 -9 6 224 224 222
12 -9 6 224 224 222
13 -9 6 224 224 222
14 -9 6 93 50 19
15 -9 6 215 188 117
10 -8 6 224 224 222
11 -8 6 224 224 222
12 -8 6 224 224 222
13 -8 6 224 224 222
14 -8 6 93 50 19
15 -8 6 215 188 117
10 -7 6 224 224 222
11 -7 6 224 224 222
12 -7 6 224 224 222
13 -7 6 224 224 222
14 -7 6 93 50 19
15 -7 6 215 188 117
11 -6 6 224 224 222
12 -6 6 224 224 222
13 -6 6 224 224 222
14 -6 6 93 50 19
15 -6 6 215 188 117
10 -5 6 224 224 222
11 -5 6 224 224 222
12 -5 6 224 224 222
13 -5 6 224 224 222
14 -5 6 93 50 19
15 -5 6 215 188 117
10 -4 6 224 224 222
11 -4 6 224 224 222
12 -4 6 224 224 222
13 -4 6 224 224 222
14 -4 6 93 50 19
15 -4 6 215 188 117
10 -3 6 224 224 222
11 -3 6 224 224 222
12 -3 6 224 224 222
13 -3 6 224 224 222
14 -3 6 93 50 19
15 -3 6 215 188 117
10 -2 6 224 224 222
11 -2 6 224 224 222
12 -2 6 224 224 222
13 -2 6 224 224 222
14 -2 6 93 50 19
15 -2 6 215 188 117
10 -1 6 224 224 222
11 -1 6 224 224 222
12 -1 6 224 224 222
13 -1 6 224 224 222
14 -1 6 93 50 19
15 -1 6 215 188 117
14 0 6 93 50 19
15 0 6 215 188 117
14 1 6 93 50 19
15 1 6 215 188 117
14 2 6 93 50 19
15 2 6 215 188 117
15 3 6 215 188 117
15 4 6 215 188 117
15 5 6 215 188 117
15 6 6 215 188 117
15 7 6 215 188 117
15 8 6 215 188 117
2 9 6 93 50 19
3 9 6 93 50 19
4 9 6 93 50 19
5 9 6 56 38 31
6 9 6 82 44 17
7 9 6 56 38 31
8 9 6 93 50 19
9 9 6 93 50 19
10 9 6 93 50 19
15 9 6 215 188 117
1 10 6 121 63 25
2 10 6 93 50 19
3 10 6 93 50 19
4 10 6 93 50 19
5 10 6 93 50 19
6 10 6 93 50 19
7 10 6 93 50 19
8 10 6 93 50 19
9 10 6 93 50 19
10 10 6 93 50 19
11 10 6 121 63 25
15 10 6 215 188 117
1 11 6 121 63 25
2 11 6 93 50 19
3 11 6 93 50 19
4 11 6 93 50 19
5 11 6 93 50 19
6 11 6 93 50 19
7 11 6 93 50 19
8 11 6 93 50 19
9 11 6 93 50 19
10 11 6 93 50 19
11 11 6 121 63 25
15 11 6 215 188 117
1 12 6 121 63 25
2 12 6 93 50 19
3 12 6 93 50 19
4 12 6 93 50 19
5 12 6 93 50 19
6 12 6 93 50 19
7 12 6 93 50 19
8 12 6 93 50 19
9 12 6 93 50 19
10 12 6 93 50 19
11 12 6 121 63 25
15 12 6 215 188 117
-13 13 6 70 147 25
-12 13 6 70 147 25
-11 13 6 70 147 25
-10 13 6 70 147 25
-9 13 6 70 147 25
-8 13 6 70 147 25
-7 13 6 70 147 25
1 13 6 121 63 25
2 13 6 93 50 19
3 13 6 93 50 19
4 13 6 93 50 19
5 13 6 93 50 19
6 13 6 93 50 19
7 13 6 93 50 19
8 13 6 93 50 19
9 13 6 93 50 19
10 13 6 93 50 19
11 13 6 121 63 25
15 13 6 215 188 117
-13 14 6 70 147 25
-12 14 6 70 147 25
-11 14 6 70 147 25
-10 14 6 70 147 25
-9 14 6 70 147 25
-8 14 6 70 147 25
-7 14 6 70 147 25
1 14 6 121 63 25
2 14 6 93 50 19
3 14 6 93 50 19
4 14 6 93 50 19
5 14 6 93 50 19
6 14 6 93 50 19
7 14 6 93 50 19
8 14 6 93 50 19
9 14 6 93 50 19
10 14 6 93 50 19
11 14 6 121 63 25
15 14 6 215 188 117
-16 15 6 136 83 31
-15 15 6 215 188 117
-14 15 6 215 188 117
-13 15 6 215 188 117
-12 15 6 215 188 117
-11 15 6 215 188 117
-10 15 6 215 188 117
-9 15 6 215 188 117
-8 15 6 215 188 117
-7 15 6 215 188 117
-6 15 6 215 188 117
-5 15 6 215 188 117
-4 15 6 215 188 117
-3 15 6 215 188 117
-2 15 6 215 188 117
-1 15 6 215 188 117
0 15 6 215 188 117
1 15 6 215 188 117
2 15 6 215 188 117
3 15 6 215 188 117
4 15 6 215 188 117
5 15 6 215 188 117
6 15 6 215 188 117
7 15 6 215 188 117
8 15 6 215 188 117
9 15 6 215 188 117
10 15 6 215 188 117
11 15 6 215 188 117
12 15 6 215 188 117
13 15 6 215 188 117
14 15 6 215 188 117
15 15 6 215 188 117
15 -16 7 136 83 31
15 -15 7 215 188 117
14 -14 7 93 50 19
15 -14 7 215 188 117
14 -13 7 93 50 19
15 -13 7 215 188 117
12 -12 7 224 224 222
13 -12 7 224 224 222
14 -12 7 93 50 19
15 -12 7 215 188 117
11 -11 7 224 224 222
12 -11 7 224 224 222
13 -11 7 224 224 222
14 -11 7 93 50 19
15 -11 7 215 188 117
11 -10 7 224 224 222
12 -10 7 224 224 222
13 -10 7 224 224 222
14 -10 7 93 50 19
15 -10 7 215 188 117
11 -9 7 224 224 222
12 -9 7 224 224 222
13 -9 7 224 224 222
14 -9 7 93 50 19
15 -9 7 215 188 117
10 -8 7 224 224 222
11 -8 7 224 224 222
12 -8 7 224 224 222
13 -8 7 224 224 222
14 -8 7 93 50 19
15 -8 7 215 188 117
11 -7 7 224 224 222
12 -7 7 224 224 222
14 -7 7 93 50 19
15 -7 7 215 188 117
14 -6 7 93 50 19
15 -6 7 215 188 117
12 -5 7 224 224 222
13 -5 7 224 224 222
14 -5 7 93 50 19
15 -5 7 215 188 117
11 -4 7 224 224 222
12 -4 7 224 224 222
13 -4 7 224 224 222
14 -4 7 93 50 19
15 -4 7 215 188 117
11 -3 7 224 224 222
12 -3 7 224 224 222
13 -3 7 224 224 222
14 -3 7 93 50 19
15 -3 7 215 188 117
11 -2 7 224 224 222
12 -2 7 224 224 222
13 -2 7 224 224 222
14 -2 7 93 50 19
15 -2 7 215 188 117
11 -1 7 224 224 222
12 -1 7 224 224 222
14 -1 7 93 50 19
15 -1 7 215 188 117
14 0 7 93 50 19
15 0 7 215 188 117
14 1 7 93 50 19
15 1 7 215 188 117
14 2 7 93 50 19
15 2 7 215 188 117
15 3 7 215 188 117
15 4 7 215 188 117
15 5 7 215 188 117
15 6 7 215 188 117
15 7 7 215 188 117
15 8 7 215 188 117
2 9 7 93 50 19
3 9 7 93 50 19
4 9 7 93 50 19
5 9 7 56 38 31
6 9 7 82 44 17
7 9 7 56 38 31
8 9 7 93 50 19
9 9 7 93 50 19
10 9 7 93 50 19
15 9 7 215 188 117
1 10 7 121 63 25
2 10 7 93 50 19
3 10 7 93 50 19
4 10 7 93 50 19
5 10 7 93 50 19
6 10 7 93 50 19
7 10 7 93 50 19
8 10 7 93 50 19
9 10 7 93 50 19
10 10 7 93 50 19
11 10 7 121 63 25
15 10 7 215 188 117
1 11 7 121 63 25
2 11 7 93 50 19
3 11 7 93 50 19
4 11 7 93 50 19
5 11 7 93 50 19
6 11 7 93 50 19
7 11 7 93 50 19
8 11 7 93 50 19
9 11 7 93 50 19
10 11 7 93 50 19
11 11 7 121 63 25
15 11 7 215 188 117
1 12 7 121 63 25
2 12 7 93 50 19
3 12 7 93 50 19
4 12 7 93 50 19
5 12 7 93 50 19
6 12 7 93 50 19
7 12 7 93 50 19
8 12 7 93 50 19
9 12 7 93 50 19
10 12 7 93 50 19
11 12 7 121 63 25
15 12 7 215 188 117
-13 13 7 70 147 25
-12 13 7 70 147 25
-11 13 7 70 147 25
-10 13 7 70 147 25
-9 13 7 70 147 25
-8 13 7 70 147 25
-7 13 7 70 147 25
1 13 7 121 63 25
2 13 7 93 50 19
3 13 7 93 50 19
4 13 7 93 50 19
5 13 7 93 50 19
6 13 7 93 50 19
7 13 7 93 50 19
8 13 7 93 50 19
9 13 7 93 50 19
10 13 7 93 50 19
11 13 7 121 63 25
15 13 7 215 188 117
-13 14 7 70 147 25
-12 14 7 70 147 25
-11 14 7 70 147 25
-10 14 7 70 147 25
-9 14 7 70 147 25
-8 14 7 70 147 25
-7 14 7 70 147 25
1 14 7 121 63 25
2 14 7 93 50 19
3 14 7 93 50 19
4 14 7 93 50 19
5 14 7 93 50 19
6 14 7 93 50 19
7 14 7 93 50 19
8 14 7 93 50 19
9 14 7 93 50 19
10 14 7 93 50 19
11 14 7 121 63 25
15 14 7 215 188 117
-16 15 7 136 83 31
-15 15 7 215 188 117
-14 15 7 215 188 117
-13 15 7 215 188 117
-12 15 7 215 188 117
-11 15 7 215 188 117
-10 15 7 215 188 117
-9 15 7 215 188 117
-8 15 7 215 188 117
-7 15 7 215 188 117
-6 15 7 215 188 117
-5 15 7 215 188 117
-4 15 7 215 188 117
-3 15 7 215 188 117
-2 15 7 215 188 117
-1 15 7 215 188 117
0 15 7 215 188 117
1 15 7 215 188 117
2 15 7 215 188 117
3 15 7 215 188 117
4 15 7 215 188 117
5 15 7 215 188 117
6 15 7 215 188 117
7 15 7 215 188 117
8 15 7 215 188 117
9 15 7 215 188 117
10 15 7 215 188 117
11 15 7 215 188 117
12 15 7 215 188 117
13 15 7 215 188 117
14 15 7 215 188 117
15 15 7 215 188 117
15 -16 8 136 83 31
15 -15 8 215 188 117
14 -14 8 93 50 19
15 -14 8 215 188 117
14 -13 8 93 50 19
15 -13 8 215 188 117
14 -12 8 93 50 19
15 -12 8 215 188 117
14 -11 8 93 50 19
15 -11 8 215 188 117
14 -10 8 93 50 19
15 -10 8 215 188 117
14 -9 8 93 50 19
15 -9 8 215 188 117
14 -8 8 93 50 19
15 -8 8 215 188 117
14 -7 8 93 50 19
15 -7 8 215 188 117
14 -6 8 93 50 19
15 -6 8 215 188 117
14 -5 8 93 50 19
15 -5 8 215 188 117
14 -4 8 93 50 19
15 -4 8 215 188 117
14 -3 8 93 50 19
15 -3 8 215 188 117
14 -2 8 93 50 19
15 -2 8 215 188 117
14 -1 8 93 50 19
15 -1 8 215 188 117
14 0 8 93 50 19
15 0 8 215 188 117
14 1 8 93 50 19
15 1 8 215 188 117
14 2 8 93 50 19
15 2 8 215 188 117
15 3 8 215 188 117
15 4 8 215 188 117
15 5 8 215 188 117
15 6 8 215 188 117
15 7 8 215 188 117
15 8 8 215 188 117
2 9 8 93 50 19
3 9 8 93 50 19
4 9 8 93 50 19
5 9 8 93 50 19
6 9 8 82 44 17
7 9 8 93 50 19
8 9 8 93 50 19
9 9 8 93 50 19
10 9 8 93 50 19
15 9 8 215 188 117
1 10 8 121 63 25
2 10 8 93 50 19
3 10 8 93 50 19
4 10 8 93 50 19
5 10 8 93 50 19
6 10 8 93 50 19
7 10 8 93 50 19
8 10 8 93 50 19
9 10 8 93 50 19
10 10 8 93 50 19
11 10 8 121 63 25
15 10 8 215 188 117
1 11 8 121 63 25
2 11 8 93 50 19
3 11 8 93 50 19
4 11 8 93 50 19
5 11 8 93 50 19
6 11 8 93 50 19
7 11 8 93 50 19
8 11 8 93 50 19
9 11 8 93 50 19
10 11 8 93 50 19
11 11 8 121 63 25
15 11 8 215 188 117
1 12 8 121 63 25
2 12 8 93 50 19
3 12 8 93 50 19
4 12 8 93 50 19
5 12 8 93 50 19
6 12 8 93 50 19
7 12 8 93 50 19
8 12 8 93 50 19
9 12 8 93 50 19
10 12 8 93 50 19
11 12 8 121 63 25
15 12 8 215 188 117
-13 13 8 70 147 25
-12 13 8 70 147 25
-11 13 8 70 147 25
-10 13 8 70 147 25
-9 13 8 70 147 25
-8 13 8 70 147 25
-7 13 8 70 147 25
1 13 8 121 63 25
2 13 8 93 50 19
3 13 8 93 50 19
4 13 8 93 50 19
5 13 8 93 50 19
6 13 8 93 50 19
7 13 8 93 50 19
8 13 8 93 50 19
9 13 8 93 50 19
10 13 8 93 50 19
11 13 8 121 63 25
15 13 8 215 188 117
-13 14 8 70 147 25
-12 14 8 70 147 25
-11 14 8 70 147 25
-10 14 8 70 147 25
-9 14 8 70 147 25
-8 14 8 70 147 25
-7 14 8 70 147 25
1 14 8 121 63 25
2 14 8 93 50 19
3 14 8 93 50 19
4 14 8 93 50 19
5 14 8 93 50 19
6 14 8 93 50 19
7 14 8 93 50 19
8 14 8 93 50 19
9 14 8 93 50 19
10 14 8 93 50 19
11 14 8 121 63 25
15 14 8 215 188 117
-16 15 8 136 83 31
-15 15 8 215 188 117
-14 15 8 215 188 117
-13 15 8 215 188 117
-12 15 8 215 188 117
-11 15 8 215 188 117
-10 15 8 215 188 117
-9 15 8 215 188 117
-8 15 8 215 188 117
-7 15 8 215 188 117
-6 15 8 215 188 117
-5 15 8 215 188 117
-4 15 8 215 188 117
-3 15 8 215 188 117
-2 15 8 215 188 117
-1 15 8 215 188 117
0 15 8 215 188 117
1 15 8 215 188 117
2 15 8 215 188 117
3 15 8 215 188 117
4 15 8 215 188 117
5 15 8 215 188 117
6 15 8 215 188 117
7 15 8 215 188 117
8 15 8 215 188 117
9 15 8 215 188 117
10 15 8 215 188 117
11 15 8 215 188 117
12 15 8 215 188 117
13 15 8 215 188 117
14 15 8 215 188 117
15 15 8 215 188 117
15 -16 9 136 83 31
15 -15 9 215 188 117
14 -14 9 93 50 19
15 -14 9 215 188 117
14 -13 9 93 50 19
15 -13 9 215 188 117
14 -12 9 93 50 19
15 -12 9 215 188 117
14 -11 9 93 50 19
15 -11 9 215 188 117
14 -10 9 93 50 19
15 -10 9 215 188 117
14 -9 9 93 50 19
15 -9 9 215 188 117
14 -8 9 93 50 19
15 -8 9 215 188 117
14 -7 9 93 50 19
15 -7 9 215 188 117
14 -6 9 93 50 19
15 -6 9 215 188 117
14 -5 9 93 50 19
15 -5 9 215 188 117
14 -4 9 93 50 19
15 -4 9 215 188 117
14 -3 9 93 50 19
15 -3 9 215 188 117
14 -2 9 93 50 19
15 -2 9 215 188 117
14 -1 9 93 50 19
15 -1 9 215 188 117
14 0 9 93 50 19
15 0 9 215 188 117
14 1 9 93 50 19
15 1 9 215 188 117
14 2 9 93 50 19
15 2 9 215 188 117
15 3 9 215 188 117
15 4 9 215 188 117
15 5 9 215 188 117
15 6 9 215 188 117
15 7 9 215 188 117
15 8 9 215 188 117
2 9 9 93 50 19
3 9 9 93 50 19
4 9 9 93 50 19
5 9 9 93 50 19
6 9 9 82 44 17
7 9 9 93 50 19
8 9 9 93 50 19
9 9 9 93 50 19
10 9 9 93 50 19
15 9 9 215 188 117
1 10 9 121 63 25
2 10 9 93 50 19
3 10 9 93 50 19
4 10 9 93 50 19
5 10 9 93 50 19
6 10 9 93 50 19
7 10 9 93 50 19
8 10 9 93 50 19
9 10 9 93 50 19
10 10 9 93 50 19
11 10 9 121 63 25
15 10 9 215 188 117
1 11 9 121 63 25
2 11 9 93 50 19
3 11 9 93 50 19
4 11 9 93 50 19
5 11 9 93 50 19
6 11 9 93 50 19
7 11 9 93 50 19
8 11 9 93 50 19
9 11 9 93 50 19
10 11 9 93 50 19
11 11 9 121 63 25
15 11 9 215 188 117
1 12 9 121 63 25
2 12 9 93 50 19
3 12 9 93 50 19
4 12 9 93 50 19
5 12 9 93 50 19
6 12 9 93 50 19
7 12 9 93 50 19
8 12 9 93 50 19
9 12 9 93 50 19
10 12 9 93 50 19
11 12 9 121 63 25
15 12 9 215 188 117
-13 13 9 70 147 25
-12 13 9 70 147 25
-11 13 9 70 147 25
-10 13 9 70 147 25
-9 13 9 70 147 25
-8 13 9 70 147 25
-7 13 9 70 147 25
1 13 9 121 63 25
2 13 9 93 50 19
3 13 9 93 50 19
4 13 9 93 50 19
5 13 9 93 50 19
6 13 9 93 50 19
7 13 9 93 50 19
8 13 9 93 50 19
9 13 9 93 50 19
10 13 9 93 50 19
11 13 9 121 63 25
15 13 9 215 188 117
-13 14 9 70 147 25
-12 14 9 70 147 25
-11 14 9 70 147 25
-10 14 9 70 147 25
-9 14 9 70 147 25
-8 14 9 70 147 25
-7 14 9 70 147 25
1 14 9 121 63 25
2 14 9 93 50 19
3 14 9 93 50 19
4 14 9 93 50 19
5 14 9 93 50 19
6 14 9 93 50 19
7 14 9 93 50 19
8 14 9 93 50 19
9 14 9 93 50 19
10 14 9 93 50 19
11 14 9 121 63 25
15 14 9 215 188 117
-16 15 9 136 83 31
-15 15 9 215 188 117
-14 15 9 215 188 117
-13 15 9 215 188 117
-12 15 9 215 188 117
-11 15 9 215 188 117
-10 15 9 215 188 117
-9 15 9 215 188 117
-8 15 9 215 188 117
-7 15 9 215 188 117
-6 15 9 215 188 117
-5 15 9 215 188 117
-4 15 9 215 188 117
-3 15 9 215 188 117
-2 15 9 215 188 117
-1 15 9 215 188 117
0 15 9 215 188 117
1 15 9 215 188 117
2 15 9 215 188 117
3 15 9 215 188 117
4 15 9 215 188 117
5 15 9 215 188 117
6 15 9 215 188 117
7 15 9 215 188 117
8 15 9 215 188 117
9 15 9 215 188 117
10 15 9 215 188 117
11 15 9 215 188 117
12 15 9 215 188 117
13 15 9 215 188 117
14 15 9 215 188 117
15 15 9 215 188 117
15 -16 10 136 83 31
15 -15 10 215 188 117
15 -14 10 215 188 117
15 -13 10 215 188 117
15 -12 10 215 188 117
15 -11 10 215 188 117
15 -10 10 215 188 117
15 -9 10 215 188 117
15 -8 10 215 188 117
15 -7 10 215 188 117
15 -6 10 215 188 117
15 -5 10 215 188 117
15 -4 10 215 188 117
15 -3 10 215 188 117
15 -2 10 215 188 117
15 -1 10 215 188 117
15 0 10 215 188 117
15 1 10 215 188 117
15 2 10 215 188 117
15 3 10 215 188 117
15 4 10 215 188 117
15 5 10 215 188 117
15 6 10 215 188 117
15 7 10 215 188 117
15 8 10 215 188 117
2 9 10 93 50 19
3 9 10 93 50 19
4 9 10 93 50 19
5 9 10 93 50 19
6 9 10 82 44 17
7 9 10 93 50 19
8 9 10 93 50 19
9 9 10 93 50 19
10 9 10 93 50 19
15 9 10 215 188 117
1 10 10 121 63 25
2 10 10 93 50 19
3 10 10 93 50 19
4 10 10 93 50 19
5 10 10 93 50 19
6 10 10 93 50 19
7 10 10 93 50 19
8 10 10 93 50 19
9 10 10 93 50 19
10 10 10 93 50 19
11 10 10 121 63 25
15 10 10 215 188 117
1 11 10 121 63 25
2 11 10 93 50 19
3 11 10 93 50 19
4 11 10 93 50 19
5 11 10 93 50 19
6 11 10 93 50 19
7 11 10 93 50 19
8 11 10 93 50 19
9 11 10 93 50 19
10 11 10 93 50 19
11 11 10 121 63 25
15 11 10 215 188 117
1 12 10 121 63 25
2 12 10 93 50 19
3 12 10 93 50 19
4 12 10 93 50 19
5 12 10 93 50 19
6 12 10 93 50 19
7 12 10 93 50 19
8 12 10 93 50 19
9 12 10 93 50 19
10 12 10 93 50 19
11 12 10 121 63 25
15 12 10 215 188 117
-13 13 10 70 147 25
-12 13 10 70 147 25
-11 13 10 70 147 25
-10 13 10 70 147 25
-9 13 10 70 147 25
-8 13 10 70 147 25
-7 13 10 70 147 25
1 13 10 121 63 25
2 13 10 93 50 19
3 13 10 93 50 19
4 13 10 93 50 19
5 13 10 93 50 19
6 13 10 93 50 19
7 13 10 93 50 19
8 13 10 93 50 19
9 13 10 93 50 19
10 13 10 93 50 19
11 13 10 121 63 25
15 13 10 215 188 117
-13 14 10 70 147 25
-12 14 10 70 147 25
-11 14 10 70 147 25
-10 14 10 70 147 25
-9 14 10 70 147 25
-8 14 10 70 147 25
-7 14 10 70 147 25
1 14 10 121 63 25
2 14 10 93 50 19
3 14 10 93 50 19
4 14 10 93 50 19
5 14 10 93 50 19
6 14 10 93 50 19
7 14 10 93 50 19
8 14 10 93 50 19
9 14 10 93 50 19
10 14 10 93 50 19
11 14 10 121 63 25
15 14 10 215 188 117
-16 15 10 136 83 31
-15 15 10 215 188 117
-14 15 10 215 188 117
-13 15 10 215 188 117
-12 15 10 215 188 117
-11 15 10 215 188 117
-10 15 10 215 188 117
-9 15 10 215 188 117
-8 15 10 215 188 117
-7 15 10 215 188 117
-6 15 10 215 188 117
-5 15 10 215 188 117
-4 15 10 215 188 117
-3 15 10 215 188 117
-2 15 10 215 188 117
-1 15 10 215 188 117
0 15 10 215 188 117
1 15 10 215 188 117
2 15 10 215 188 117
3 15 10 215 188 117
4 15 10 215 188 117
5 15 10 215 188 117
6 15 10 215 188 117
7 15 10 215 188 117
8 15 10 215 188 117
9 15 10 215 188 117
10 15 10 215 188 117
11 15 10 215 188 117
12 15 10 215 188 117
13 15 10 215 188 117
14 15 10 215 188 117
15 15 10 215 188 117
15 -16 11 136 83 31
15 -15 11 215 188 117
15 -14 11 215 188 117
15 -13 11 215 188 117
15 -12 11 215 188 117
15 -11 11 215 188 117
15 -10 11 215 188 117
15 -9 11 215 188 117
15 -8 11 215 188 117
15 -7 11 215 188 117
15 -6 11 215 188 117
15 -5 11 215 188 117
15 -4 11 215 188 117
15 -3 11 215 188 117
15 -2 11 215 188 117
15 -1 11 215 188 117
15 0 11 215 188 117
15 1 11 215 188 117
15 2 11 215 188 117
15 3 11 215 188 117
15 4 11 215 188 117
15 5 11 215 188 117
15 6 11 215 188 117
15 7 11 215 188 117
15 8 11 215 188 117
2 9 11 93 50 19
3 9 11 93 50 19
4 9 11 93 50 19
5 9 11 93 50 19
6 9 11 82 44 17
7 9 11 93 50 19
8 9 11 93 50 19
9 9 11 93 50 19
10 9 11 93 50 19
15 9 11 215 188 117
1 10 11 121 63 25
2 10 11 93 50 19
3 10 11 93 50 19
4 10 11 93 50 19
5 10 11 93 50 19
6 10 11 93 50 19
7 10 11 93 50 19
8 10 11 93 50 19
9 10 11 93 50 19
10 10 11 93 50 19
11 10 11 121 63 25
15 10 11 215 188 117
1 11 11 121 63 25
2 11 11 93 50 19
3 11 11 93 50 19
4 11 11 93 50 19
5 11 11 93 50 19
6 11 11 93 50 19
7 11 11 93 50 19
8 11 11 93 50 19
9 11 11 93 50 19
10 11 11 93 50 19
11 11 11 121 63 25
15 11 11 215 188 117
1 12 11 121 63 25
2 12 11 93 50 19
3 12 11 93 50 19
4 12 11 93 50 19
5 12 11 93 50 19
6 12 11 93 50 19
7 12 11 93 50 19
8 12 11 93 50 19
9 12 11 93 50 19
10 12 11 93 50 19
11 12 11 121 63 25
15 12 11 215 188 117
-13 13 11 70 147 25
-12 13 11 70 147 25
-11 13 11 70 147 25
-10 13 11 70 147 25
-9 13 11 70 147 25
-8 13 11 70 147 25
-7 13 11 70 147 25
1 13 11 121 63 25
2 13 11 93 50 19
3 13 11 93 50 19
4 13 11 93 50 19
5 13 11 93 50 19
6 13 11 93 50 19
7 13 11 93 50 19
8 13 11 93 50 19
9 13 11 93 50 19
10 13 11 93 50 19
11 13 11 121 63 25
15 13 11 215 188 117
-13 14 11 70 147 25
-12 14 11 70 147 25
-11 14 11 70 147 25
-10 14 11 70 147 25
-9 14 11 70 147 25
-8 14 11 70 147 25
-7 14 11 70 147 25
1 14 11 121 63 25
2 14 11 93 50 19
3 14 11 93 50 19
4 14 11 93 50 19
5 14 11 93 50 19
6 14 11 93 50 19
7 14 11 93 50 19
8 14 11 93 50 19
9 14 11 93 50 19
10 14 11 93 50 19
11 14 11 121 63 25
15 14 11 215 188 117
-16 15 11 136 83 31
-15 15 11 215 188 117
-14 15 11 215 188 117
-13 15 11 215 188 117
-12 15 11 215 188 117
-11 15 11 215 188 117
-10 15 11 215 188 117
-9 15 11 215 188 117
-8 15 11 215 188 117
-7 15 11 215 188 117
-6 15 11 215 188 117
-5 15 11 215 188 117
-4 15 11 215 188 117
-3 15 11 215 188 117
-2 15 11 215 188 117
-1 15 11 215 188 117
0 15 11 215 188 117
1 15 11 215 188 117
2 15 11 215 188 117
3 15 11 215 188 117
4 15 11 215 188 117
5 15 11 215 188 117
6 15 11 215 188 117
7 15 11 215 188 117
8 15 11 215 188 117
9 15 11 215 188 117
10 15 11 215 188 117
11 15 11 215 188 117
12 15 11 215 188 117
13 15 11 215 188 117
14 15 11 215 188 117
15 15 11 215 188 117
15 -16 12 136 83 31
15 -15 12 93 50 19
15 -14 12 93 50 19
15 -13 12 93 50 19
15 -12 12 93 50 19
15 -11 12 93 50 19
15 -10 12 93 50 19
15 -9 12 93 50 19
15 -8 12 93 50 19
15 -7 12 93 50 19
15 -6 12 93 50 19
15 -5 12 93 50 19
15 -4 12 93 50 19
15 -3 12 93 50 19
15 -2 12 93 50 19
15 -1 12 93 50 19
15 0 12 93 50 19
15 1 12 93 50 19
15 2 12 93 50 19
15 3 12 93 50 19
15 4 12 93 50 19
15 5 12 93 50 19
15 6 12 93 50 19
15 7 12 93 50 19
15 8 12 93 50 19
2 9 12 93 50 19
3 9 12 93 50 19
4 9 12 93 50 19
5 9 12 93 50 19
6 9 12 82 44 17
7 9 12 93 50 19
8 9 12 93 50 19
9 9 12 93 50 19
10 9 12 93 50 19
15 9 12 93 50 19
1 10 12 121 63 25
2 10 12 93 50 19
3 10 12 93 50 19
4 10 12 93 50 19
5 10 12 93 50 19
6 10 12 93 50 19
7 10 12 93 50 19
8 10 12 93 50 19
9 10 12 93 50 19
10 10 12 93 50 19
11 10 12 121 63 25
15 10 12 93 50 19
1 11 12 121 63 25
2 11 12 93 50 19
3 11 12 93 50 19
4 11 12 93 50 19
5 11 12 93 50 19
6 11 12 93 50 19
7 11 12 93 50 19
8 11 12 93 50 19
9 11 12 93 50 19
10 11 12 93 50 19
11 11 12 121 63 25
15 11 12 93 50 19
1 12 12 121 63 25
2 12 12 93 50 19
3 12 12 93 50 19
4 12 12 93 50 19
5 12 12 93 50 19
6 12 12 93 50 19
7 12 12 93 50 19
8 12 12 93 50 19
9 12 12 93 50 19
10 12 12 93 50 19
11 12 12 121 63 25
15 12 12 93 50 19
1 13 12 121 63 25
2 13 12 93 50 19
3 13 12 93 50 19
4 13 12 93 50 19
5 13 12 93 50 19
6 13 12 93 50 19
7 13 12 93 50 19
8 13 12 93 50 19
9 13 12 93 50 19
10 13 12 93 50 19
11 13 12 121 63 25
15 13 12 93 50 19
1 14 12 121 63 25
2 14 12 93 50 19
3 14 12 93 50 19
4 14 12 93 50 19
5 14 12 93 50 19
6 14 12 93 50 19
7 14 12 93 50 19
8 14 12 93 50 19
9 14 12 93 50 19
10 14 12 93 50 19
11 14 12 121 63 25
15 14 12 93 50 19
-16 15 12 136 83 31
-15 15 12 93 50 19
-14 15 12 93 50 19
-13 15 12 93 50 19
-12 15 12 93 50 19
-11 15 12 93 50 19
-10 15 12 93 50 19
-9 15 12 93 50 19
-8 15 12 93 50 19
-7 15 12 93 50 19
-6 15 12 93 50 19
-5 15 12 93 50 19
-4 15 12 93 50 19
-3 15 12 93 50 19
-2 15 12 93 50 19
-1 15 12 93 50 19
0 15 12 93 50 19
1 15 12 93 50 19
2 15 12 93 50 19
3 15 12 93 50 19
4 15 12 93 50 19
5 15 12 93 50 19
6 15 12 93 50 19
7 15 12 93 50 19
8 15 12 93 50 19
9 15 12 93 50 19
10 15 12 93 50 19
11 15 12 93 50 19
12 15 12 93 50 19
13 15 12 93 50 19
14 15 12 93 50 19
15 15 12 93 50 19
15 -16 13 136 83 31
15 -15 13 182 118 55
15 -14 13 182 118 55
15 -13 13 182 118 55
15 -12 13 182 118 55
15 -11 13 182 118 55
15 -10 13 182 118 55
15 -9 13 182 118 55
15 -8 13 182 118 55
15 -7 13 182 118 55
15 -6 13 182 118 55
15 -5 13 182 118 55
15 -4 13 182 118 55
15 -3 13 182 118 55
15 -2 13 182 118 55
15 -1 13 182 118 55
15 0 13 182 118 55
15 1 13 182 118 55
15 2 13 182 118 55
15 3 13 182 118 55
15 4 13 182 118 55
15 5 13 182 118 55
15 6 13 182 118 55
15 7 13 182 118 55
15 8 13 182 118 55
2 9 13 93 50 19
3 9 13 93 50 19
4 9 13 93 50 19
5 9 13 93 50 19
6 9 13 82 44 17
7 9 13 93 50 19
8 9 13 93 50 19
9 9 13 93 50 19
10 9 13 93 50 19
15 9 13 182 118 55
1 10 13 121 63 25
2 10 13 93 50 19
3 10 13 93 50 19
4 10 13 93 50 19
5 10 13 93 50 19
6 10 13 93 50 19
7 10 13 93 50 19
8 10 13 93 50 19
9 10 13 93 50 19
10 10 13 93 50 19
11 10 13 121 63 25
15 10 13 182 118 55
1 11 13 121 63 25
2 11 13 93 50 19
3 11 13 93 50 19
4 11 13 93 50 19
5 11 13 93 50 19
6 11 13 93 50 19
7 11 13 93 50 19
8 11 13 93 50 19
9 11 13 93 50 19
10 11 13 93 50 19
11 11 13 121 63 25
15 11 13 182 118 55
1 12 13 121 63 25
2 12 13 93 50 19
3 12 13 93 50 19
4 12 13 93 50 19
5 12 13 93 50 19
6 12 13 93 50 19
7 12 13 93 50 19
8 12 13 93 50 19
9 12 13 93 50 19
10 12 13 93 50 19
11 12 13 121 63 25
15 12 13 182 118 55
1 13 13 121 63 25
2 13 13 93 50 19
3 13 13 93 50 19
4 13 13 93 50 19
5 13 13 93 50 19
6 13 13 93 50 19
7 13 13 93 50 19
8 13 13 93 50 19
9 13 13 93 50 19
10 13 13 93 50 19
11 13 13 121 63 25
15 13 13 182 118 55
1 14 13 121 63 25
2 14 13 93 50 19
3 14 13 93 50 19
4 14 13 93 50 19
5 14 13 93 50 19
6 14 13 93 50 19
7 14 13 93 50 19
8 14 13 93 50 19
9 14 13 93 50 19
10 14 13 93 50 19
11 14 13 121 63 25
15 14 13 182 118 55
-16 15 13 136 83 31
-15 15 13 182 118 55
-14 15 13 182 118 55
-13 15 13 182 118 55
-12 15 13 182 118 55
-11 15 13 182 118 55
-10 15 13 182 118 55
-9 15 13 182 118 55
-8 15 13 182 118 55
-7 15 13 182 118 55
-6 15 13 182 118 55
-5 15 13 182 118 55
-4 15 13 182 118 55
-3 15 13 182 118 55
-2 15 13 182 118 55
-1 15 13 182 118 55
0 15 13 182 118 55
1 15 13 182 118 55
2 15 13 182 118 55
3 15 13 182 118 55
4 15 13 182 118 55
5 15 13 182 118 55
6 15 13 182 118 55
7 15 13 182 118 55
8 15 13 182 118 55
9 15 13 182 118 55
10 15 13 182 118 55
11 15 13 182 118 55
12 15 13 182 118 55
13 15 13 182 118 55
14 15 13 182 118 55
15 15 13 182 118 55
15 -16 14 136 83 31
15 -15 14 182 118 55
15 -14 14 182 118 55
15 -13 14 93 50 19
15 -12 14 93 50 19
15 -11 14 93 50 19
15 -10 14 93 50 19
15 -9 14 93 50 19
15 -8 14 182 118 55
15 -7 14 182 118 55
15 -6 14 182 118 55
15 -5 14 182 118 55
15 -4 14 182 118 55
15 -3 14 93 50 19
15 -2 14 93 50 19
15 -1 14 93 50 19
15 0 14 93 50 19
15 1 14 93 50 19
15 2 14 182 118 55
15 3 14 182 118 55
15 4 14 182 118 55
15 5 14 182 118 55
15 6 14 182 118 55
15 7 14 182 118 55
15 8 14 182 118 55
15 9 14 182 118 55
1 10 14 121 63 25
2 10 14 121 63 25
3 10 14 121 63 25
4 10 14 121 63 25
5 10 14 121 63 25
6 10 14 121 63 25
7 10 14 121 63 25
8 10 14 121 63 25
9 10 14 121 63 25
10 10 14 121 63 25
11 10 14 121 63 25
15 10 14 182 118 55
1 11 14 121 63 25
2 11 14 121 63 25
3 11 14 121 63 25
4 11 14 121 63 25
5 11 14 121 63 25
6 11 14 121 63 25
7 11 14 121 63 25
8 11 14 121 63 25
9 11 14 121 63 25
10 11 14 121 63 25
11 11 14 121 63 25
15 11 14 182 118 55
1 12 14 121 63 25
2 12 14 121 63 25
3 12 14 121 63 25
4 12 14 121 63 25
5 12 14 121 63 25
6 12 14 121 63 25
7 12 14 121 63 25
8 12 14 121 63 25
9 12 14 121 63 25
10 12 14 121 63 25
11 12 14 121 63 25
15 12 14 182 118 55
1 13 14 121 63 25
2 13 14 121 63 25
3 13 14 121 63 25
4 13 14 121 63 25
5 13 14 121 63 25
6 13 14 121 63 25
7 13 14 121 63 25
8 13 14 121 63 25
9 13 14 121 63 25
10 13 14 121 63 25
11 13 14 121 63 25
15 13 14 182 118 55
1 14 14 121 63 25
2 14 14 121 63 25
3 14 14 121 63 25
4 14 14 121 63 25
5 14 14 121 63 25
6 14 14 121 63 25
7 14 14 121 63 25
8 14 14 121 63 25
9 14 14 121 63 25
10 14 14 121 63 25
11 14 14 121 63 25
15 14 14 182 118 55
-16 15 14 136 83 31
-15 15 14 182 118 55
-14 15 14 182 118 55
-13 15 14 182 118 55
-12 15 14 182 118 55
-11 15 14 182 118 55
-10 15 14 182 118 55
-9 15 14 182 118 55
-8 15 14 182 118 55
-7 15 14 182 118 55
-6 15 14 182 118 55
-5 15 14 182 118 55
-4 15 14 182 118 55
-3 15 14 182 118 55
-2 15 14 182 118 55
-1 15 14 182 118 55
0 15 14 182 118 55
1 15 14 182 118 55
2 15 14 182 118 55
3 15 14 182 118 55
4 15 14 182 118 55
5 15 14 182 118 55
6 15 14 182 118 55
7 15 14 182 118 55
8 15 14 182 118 55
9 15 14 182 118 55
10 15 14 182 118 55
11 15 14 182 118 55
12 15 14 182 118 55
13 15 14 182 118 55
14 15 14 182 118 55
15 15 14 182 118 55
15 -16 15 136 83 31
15 -15 15 182 118 55
15 -14 15 182 118 55
15 -13 15 170 229 136
15 -12 15 224 224 222
15 -11 15 170 229 136
15 -10 15 170 229 136
15 -9 15 93 50 19
15 -8 15 182 118 55
15 -7 15 182 118 55
15 -6 15 182 118 55
15 -5 15 182 118 55
15 -4 15 182 118 55
15 -3 15 177 243 255
15 -2 15 233 237 141
15 -1 15 233 237 141
15 0 15 233 237 141
15 1 15 93 50 19
15 2 15 182 118 55
15 3 15 182 118 55
15 4 15 182 118 55
15 5 15 182 118 55
15 6 15 182 118 55
15 7 15 182 118 55
15 8 15 182 118 55
15 9 15 182 118 55
15 10 15 182 118 55
15 11 15 182 118 55
15 12 15 182 118 55
15 13 15 182 118 55
15 14 15 182 118 55
-16 15 15 136 83 31
-15 15 15 182 118 55
-14 15 15 182 118 55
-13 15 15 182 118 55
-12 15 15 182 118 55
-11 15 15 182 118 55
-10 15 15 182 118 55
-9 15 15 182 118 55
-8 15 15 182 118 55
-7 15 15 182 118 55
-6 15 15 182 118 55
-5 15 15 182 118 55
-4 15 15 182 118 55
-3 15 15 182 118 55
-2 15 15 182 118 55
-1 15 15 182 118 55
0 15 15 182 118 55
1 15 15 182 118 55
2 15 15 182 118 55
3 15 15 182 118 55
4 15 15 182 118 55
5 15 15 182 118 55
6 15 15 182 118 55
7 15 15 182 118 55
8 15 15 182 118 55
9 15 15 182 118 55
10 15 15 182 118 55
11 15 15 182 118 55
12 15 15 182 118 55
13 15 15 182 118 55
14 15 15 182 118 55
15 15 15 182 118 55
15 -16 16 136 83 31
15 -15 16 182 118 55
15 -14 16 182 118 55
15 -13 16 224 224 222
15 -12 16 170 229 136
15 -11 16 224 224 222
15 -10 16 170 229 136
15 -9 16 93 50 19
15 -8 16 182 118 55
15 -7 16 182 118 55
15 -6 16 182 118 55
15 -5 16 182 118 55
15 -4 16 182 118 55
15 -3 16 177 243 255
15 -2 16 177 243 255
15 -1 16 177 243 255
15 0 16 233 237 141
15 1 16 93 50 19
15 2 16 182 118 55
15 3 16 182 118 55
15 4 16 182 118 55
15 5 16 182 118 55
15 6 16 182 118 55
15 7 16 182 118 55
15 8 16 182 118 55
15 9 16 182 118 55
15 10 16 182 118 55
15 11 16 182 118 55
15 12 16 182 118 55
15 13 16 182 118 55
15 14 16 182 118 55
-16 15 16 136 83 31
-15 15 16 182 118 55
-14 15 16 182 118 55
-13 15 16 182 118 55
-12 15 16 182 118 55
-11 15 16 182 118 55
-10 15 16 182 118 55
-9 15 16 182 118 55
-8 15 16 182 118 55
-7 15 16 182 118 55
-6 15 16 182 118 55
-5 15 16 182 118 55
-4 15 16 182 118 55
-3 15 16 182 118 55
-2 15 16 182 118 55
-1 15 16 182 118 55
0 15 16 182 118 55
1 15 16 182 118 55
2 15 16 182 118 55
3 15 16 182 118 55
4 15 16 182 118 55
5 15 16 182 118 55
6 15 16 182 118 55
7 15 16 182 118 55
8 15 16 182 118 55
9 15 16 182 118 55
10 15 16 182 118 55
11 15 16 182 118 55
12 15 16 182 118 55
13 15 16 182 118 55
14 15 16 182 118 55
15 15 16 182 118 55
15 -16 17 136 83 31
15 -15 17 182 118 55
15 -14 17 182 118 55
15 -13 17 224 224 222
15 -12 17 224 224 222
15 -11 17 224 224 222
15 -10 17 224 224 222
15 -9 17 93 50 19
15 -8 17 182 118 55
15 -7 17 182 118 55
15 -6 17 182 118 55
15 -5 17 182 118 55
15 -4 17 182 118 55
15 -3 17 177 243 255
15 -2 17 177 243 255
15 -1 17 177 243 255
15 0 17 177 243 255
15 1 17 93 50 19
15 2 17 182 118 55
15 3 17 182 118 55
15 4 17 182 118 55
15 5 17 182 118 55
15 6 17 182 118 55
15 7 17 182 118 55
15 8 17 182 118 55
15 9 17 182 118 55
15 10 17 182 118 55
15 11 17 182 118 55
15 12 17 182 118 55
15 13 17 182 118 55
15 14 17 182 118 55
-16 15 17 136 83 31
-15 15 17 182 118 55
-14 15 17 182 118 55
-13 15 17 182 118 55
-12 15 17 182 118 55
-11 15 17 182 118 55
-10 15 17 182 118 55
-9 15 17 182 118 55
-8 15 17 182 118 55
-7 15 17 182 118 55
-6 15 17 182 118 55
-5 15 17 182 118 55
-4 15 17 182 118 55
-3 15 17 182 118 55
-2 15 17 182 118 55
-1 15 17 182 118 55
0 15 17 182 118 55
1 15 17 182 118 55
2 15 17 182 118 55
3 15 17 182 118 55
4 15 17 182 118 55
5 15 17 182 118 55
6 15 17 182 118 55
7 15 17 182 118 55
8 15 17 182 118 55
9 15 17 182 118 55
10 15 17 182 118 55
11 15 17 182 118 55
12 15 17 182 118 55
13 15 17 182 118 55
14 15 17 182 118 55
15 15 17 182 118 55
15 -16 18 136 83 31
15 -15 18 182 118 55
15 -14 18 182 118 55
15 -13 18 182 118 55
15 -12 18 182 118 55
15 -11 18 182 118 55
15 -10 18 182 118 55
15 -9 18 182 118 55
15 -8 18 182 118 55
15 -7 18 182 118 55
15 -6 18 182 118 55
15 -5 18 182 118 55
15 -4 18 182 118 55
15 -3 18 182 118 55
15 -2 18 182 118 55
15 -1 18 182 118 55
15 0 18 182 118 55
15 1 18 182 118 55
15 2 18 182 118 55
15 3 18 182 118 55
15 4 18 182 118 55
15 5 18 182 118 55
15 6 18 182 118 55
15 7 18 182 118 55
15 8 18 182 118 55
15 9 18 182 118 55
15 10 18 182 118 55
15 11 18 182 118 55
15 12 18 182 118 55
15 13 18 182 118 55
15 14 18 182 118 55
-16 15 18 136 83 31
-15 15 18 182 118 55
-14 15 18 182 118 55
-13 15 18 182 118 55
-12 15 18 182 118 55
-11 15 18 182 118 55
-10 15 18 182 118 55
-9 15 18 182 118 55
-8 15 18 182 118 55
-7 15 18 182 118 55
-6 15 18 182 118 55
-5 15 18 182 118 55
-4 15 18 182 118 55
-3 15 18 182 118 55
-2 15 18 182 118 55
-1 15 18 182 118 55
0 15 18 182 118 55
1 15 18 182 118 55
2 15 18 182 118 55
3 15 18 182 118 55
4 15 18 182 118 55
5 15 18 182 118 55
6 15 18 182 118 55
7 15 18 182 118 55
8 15 18 182 118 55
9 15 18 182 118 55
10 15 18 182 118 55
11 15 18 182 118 55
12 15 18 182 118 55
13 15 18 182 118 55
14 15 18 182 118 55
15 15 18 182 118 55
15 -16 19 136 83 31
15 -15 19 136 83 31
15 -14 19 136 83 31
15 -13 19 136 83 31
15 -12 19 136 83 31
15 -11 19 136 83 31
15 -10 19 136 83 31
15 -9 19 136 83 31
15 -8 19 136 83 31
15 -7 19 136 83 31
15 -6 19 136 83 31
15 -5 19 136 83 31
15 -4 19 136 83 31
15 -3 19 136 83 31
15 -2 19 136 83 31
15 -1 19 136 83 31
15 0 19 136 83 31
15 1 19 136 83 31
15 2 19 136 83 31
15 3 19 136 83 31
15 4 19 136 83 31
15 5 19 136 83 31
15 6 19 136 83 31
15 7 19 136 83 31
15 8 19 136 83 31
15 9 19 136 83 31
15 10 19 136 83 31
15 11 19 136 83 31
15 12 19 136 83 31
15 13 19 136 83 31
15 14 19 136 83 31
-16 15 19 136 83 31
-15 15 19 136 83 31
-14 15 19 136 83 31
-13 15 19 136 83 31
-12 15 19 136 83 31
-11 15 19 136 83 31
-10 15 19 136 83 31
-9 15 19 136 83 31
-8 15 19 136 83 31
-7 15 19 136 83 31
-6 15 19 136 83 31
-5 15 19 136 83 31
-4 15 19 136 83 31
-3 15 19 136 83 31
-2 15 19 136 83 31
-1 15 19 136 83 31
0 15 19 136 83 31
1 15 19 136 83 31
2 15 19 136 83 31
3 15 19 136 83 31
4 15 19 136 83 31
5 15 19 136 83 31
6 15 19 136 83 31
7 15 19 136 83 31
8 15 19 136 83 31
9 15 19 136 83 31
10 15 19 136 83 31
11 15 19 136 83 31
12 15 19 136 83 31
13 15 19 136 83 31
14 15 19 136 83 31
15 15 19 136 83 31
