ply
format ascii 1.0
comment : MagicaVoxel @ Ephtracy
element vertex 556
property float x
property float y
property float z
property uchar red
property uchar green
property uchar blue
end_header
-1 -2 0 238 238 238
0 -2 0 238 238 238
-2 -1 0 238 238 238
-1 -1 0 136 81 29
0 -1 0 136 81 29
1 -1 0 238 238 238
-2 0 0 238 238 238
-1 0 0 136 81 29
0 0 0 136 81 29
1 0 0 238 238 238
-1 1 0 238 238 238
0 1 0 238 238 238
-1 -1 1 136 81 29
0 -1 1 131 77 28
-1 0 1 131 77 28
0 0 1 136 81 29
-1 -1 2 136 81 29
0 -1 2 136 81 29
-1 0 2 136 81 29
0 0 2 131 77 28
-1 -1 3 136 81 29
0 -1 3 136 81 29
-1 0 3 131 77 28
0 0 3 136 81 29
-1 -1 4 136 81 29
0 -1 4 136 81 29
-1 0 4 136 81 29
0 0 4 136 81 29
-1 -1 5 136 81 29
0 -1 5 136 81 29
-1 0 5 136 81 29
0 0 5 136 81 29
-2 -4 6 34 131 45
-1 -4 6 34 131 45
0 -4 6 34 131 45
1 -4 6 34 131 45
-3 -3 6 13 118 25
-2 -3 6 34 131 45
-1 -3 6 34 131 45
0 -3 6 34 131 45
1 -3 6 34 131 45
2 -3 6 34 131 45
-4 -2 6 13 118 25
-3 -2 6 34 131 45
-2 -2 6 34 131 45
-1 -2 6 34 131 45
0 -2 6 34 131 45
1 -2 6 34 131 45
2 -2 6 34 131 45
3 -2 6 13 118 25
-4 -1 6 13 118 25
-3 -1 6 34 131 45
-2 -1 6 34 131 45
-1 -1 6 34 131 45
0 -1 6 34 131 45
1 -1 6 34 131 45
2 -1 6 34 131 45
3 -1 6 13 118 25
-4 0 6 13 118 25
-3 0 6 34 131 45
-2 0 6 34 131 45
-1 0 6 34 131 45
0 0 6 34 131 45
1 0 6 34 131 45
2 0 6 34 131 45
3 0 6 34 131 45
-4 1 6 34 131 45
-3 1 6 34 131 45
-2 1 6 34 131 45
-1 1 6 34 131 45
0 1 6 34 131 45
1 1 6 34 131 45
2 1 6 34 131 45
3 1 6 13 118 25
-3 2 6 34 131 45
-2 2 6 34 131 45
-1 2 6 34 131 45
0 2 6 34 131 45
1 2 6 34 131 45
2 2 6 13 118 25
-2 3 6 34 131 45
-1 3 6 34 131 45
0 3 6 34 131 45
1 3 6 13 118 25
-2 -4 7 34 131 45
-1 -4 7 34 131 45
0 -4 7 34 131 45
1 -4 7 34 131 45
-2 -3 7 34 131 45
-1 -3 7 34 131 45
0 -3 7 34 131 45
1 -3 7 34 131 45
-4 -2 7 13 118 25
-3 -2 7 34 131 45
-2 -2 7 34 131 45
-1 -2 7 34 131 45
0 -2 7 34 131 45
1 -2 7 34 131 45
2 -2 7 34 131 45
3 -2 7 34 131 45
-4 -1 7 13 118 25
-3 -1 7 34 131 45
-2 -1 7 34 131 45
-1 -1 7 34 131 45
0 -1 7 34 131 45
1 -1 7 34 131 45
2 -1 7 34 131 45
3 -1 7 13 118 25
-4 0 7 34 131 45
-3 0 7 34 131 45
-2 0 7 34 131 45
-1 0 7 34 131 45
0 0 7 34 131 45
1 0 7 34 131 45
2 0 7 34 131 45
3 0 7 34 131 45
-4 1 7 34 131 45
-3 1 7 34 131 45
-2 1 7 34 131 45
-1 1 7 34 131 45
0 1 7 34 131 45
1 1 7 34 131 45
2 1 7 13 118 25
3 1 7 34 131 45
-2 2 7 34 131 45
-1 2 7 34 131 45
0 2 7 34 131 45
1 2 7 13 118 25
-2 3 7 34 131 45
-1 3 7 34 131 45
0 3 7 34 131 45
1 3 7 13 118 25
-2 -4 8 34 131 45
-1 -4 8 13 118 25
0 -4 8 13 118 25
1 -4 8 13 118 25
-2 -3 8 34 131 45
-1 -3 8 34 131 45
0 -3 8 34 131 45
1 -3 8 34 131 45
-4 -2 8 13 118 25
-3 -2 8 34 131 45
-2 -2 8 34 131 45
-1 -2 8 34 131 45
0 -2 8 34 131 45
1 -2 8 34 131 45
2 -2 8 34 131 45
3 -2 8 34 131 45
-4 -1 8 13 118 25
-3 -1 8 34 131 45
-2 -1 8 34 131 45
-1 -1 8 34 131 45
0 -1 8 34 131 45
1 -1 8 34 131 45
2 -1 8 34 131 45
3 -1 8 34 131 45
-4 0 8 34 131 45
-3 0 8 34 131 45
-2 0 8 34 131 45
-1 0 8 34 131 45
0 0 8 34 131 45
1 0 8 34 131 45
2 0 8 34 131 45
3 0 8 34 131 45
-4 1 8 13 118 25
-3 1 8 34 131 45
-2 1 8 34 131 45
-1 1 8 34 131 45
0 1 8 34 131 45
1 1 8 34 131 45
2 1 8 34 131 45
3 1 8 34 131 45
-2 2 8 34 131 45
-1 2 8 34 131 45
0 2 8 34 131 45
1 2 8 13 118 25
-2 3 8 13 118 25
-1 3 8 13 118 25
0 3 8 34 131 45
1 3 8 13 118 25
-2 -4 9 34 131 45
-1 -4 9 13 118 25
0 -4 9 13 118 25
1 -4 9 13 118 25
-2 -3 9 34 131 45
-1 -3 9 34 131 45
0 -3 9 34 131 45
1 -3 9 34 131 45
-4 -2 9 13 118 25
-3 -2 9 34 131 45
-2 -2 9 34 131 45
-1 -2 9 34 131 45
0 -2 9 34 131 45
1 -2 9 34 131 45
2 -2 9 34 131 45
3 -2 9 34 131 45
-4 -1 9 13 118 25
-3 -1 9 34 131 45
-2 -1 9 34 131 45
-1 -1 9 34 131 45
0 -1 9 34 131 45
1 -1 9 34 131 45
2 -1 9 34 131 45
3 -1 9 34 131 45
-4 0 9 34 131 45
-3 0 9 34 131 45
-2 0 9 34 131 45
-1 0 9 34 131 45
0 0 9 34 131 45
1 0 9 34 131 45
2 0 9 34 131 45
3 0 9 34 131 45
-4 1 9 13 118 25
-3 1 9 34 131 45
-2 1 9 34 131 45
-1 1 9 34 131 45
0 1 9 34 131 45
1 1 9 34 131 45
2 1 9 34 131 45
3 1 9 34 131 45
-2 2 9 34 131 45
-1 2 9 34 131 45
0 2 9 34 131 45
1 2 9 13 118 25
-2 3 9 13 118 25
-1 3 9 34 131 45
0 3 9 34 131 45
1 3 9 13 118 25
-2 -4 10 34 131 45
-1 -4 10 34 131 45
0 -4 10 13 118 25
1 -4 10 13 118 25
-2 -3 10 34 131 45
-1 -3 10 34 131 45
0 -3 10 34 131 45
1 -3 10 34 131 45
-4 -2 10 13 118 25
-3 -2 10 34 131 45
-2 -2 10 34 131 45
-1 -2 10 34 131 45
0 -2 10 34 131 45
1 -2 10 34 131 45
2 -2 10 34 131 45
3 -2 10 13 118 25
-4 -1 10 34 131 45
-3 -1 10 34 131 45
-2 -1 10 34 131 45
-1 -1 10 34 131 45
0 -1 10 34 131 45
1 -1 10 34 131 45
2 -1 10 34 131 45
3 -1 10 34 131 45
-4 0 10 34 131 45
-3 0 10 34 131 45
-2 0 10 34 131 45
-1 0 10 34 131 45
0 0 10 34 131 45
1 0 10 34 131 45
2 0 10 34 131 45
3 0 10 34 131 45
-4 1 10 13 118 25
-3 1 10 34 131 45
-2 1 10 34 131 45
-1 1 10 34 131 45
0 1 10 34 131 45
1 1 10 34 131 45
2 1 10 34 131 45
3 1 10 34 131 45
-2 2 10 34 131 45
-1 2 10 34 131 45
0 2 10 34 131 45
1 2 10 34 131 45
-2 3 10 13 118 25
-1 3 10 34 131 45
0 3 10 34 131 45
1 3 10 13 118 25
-2 -4 11 34 131 45
-1 -4 11 13 118 25
0 -4 11 13 118 25
1 -4 11 34 131 45
-2 -3 11 34 131 45
-1 -3 11 34 131 45
0 -3 11 34 131 45
1 -3 11 34 131 45
-4 -2 11 34 131 45
-3 -2 11 34 131 45
-2 -2 11 34 131 45
-1 -2 11 34 131 45
0 -2 11 34 131 45
1 -2 11 34 131 45
2 -2 11 34 131 45
-4 -1 11 34 131 45
-3 -1 11 34 131 45
-2 -1 11 34 131 45
-1 -1 11 34 131 45
0 -1 11 34 131 45
1 -1 11 34 131 45
2 -1 11 34 131 45
3 -1 11 34 131 45
-4 0 11 34 131 45
-3 0 11 34 131 45
-2 0 11 34 131 45
-1 0 11 34 131 45
0 0 11 34 131 45
1 0 11 34 131 45
2 0 11 34 131 45
3 0 11 34 131 45
-3 1 11 13 118 25
-2 1 11 34 131 45
-1 1 11 34 131 45
0 1 11 34 131 45
1 1 11 34 131 45
2 1 11 13 118 25
3 1 11 34 131 45
-2 2 11 34 131 45
-1 2 11 34 131 45
0 2 11 34 131 45
1 2 11 13 118 25
-2 3 11 13 118 25
-1 3 11 34 131 45
0 3 11 34 131 45
1 3 11 34 131 45
-1 -4 12 34 131 45
0 -4 12 34 131 45
-2 -3 12 34 131 45
-1 -3 12 34 131 45
0 -3 12 34 131 45
1 -3 12 34 131 45
-3 -2 12 34 131 45
-2 -2 12 34 131 45
-1 -2 12 34 131 45
0 -2 12 34 131 45
1 -2 12 34 131 45
2 -2 12 34 131 45
-4 -1 12 34 131 45
-3 -1 12 34 131 45
-2 -1 12 34 131 45
-1 -1 12 34 131 45
0 -1 12 34 131 45
1 -1 12 34 131 45
2 -1 12 34 131 45
3 -1 12 13 118 25
-4 0 12 34 131 45
-3 0 12 34 131 45
-2 0 12 34 131 45
-1 0 12 34 131 45
0 0 12 34 131 45
1 0 12 34 131 45
2 0 12 34 131 45
3 0 12 34 131 45
-3 1 12 13 118 25
-2 1 12 34 131 45
-1 1 12 34 131 45
0 1 12 34 131 45
1 1 12 34 131 45
2 1 12 34 131 45
-2 2 12 13 118 25
-1 2 12 34 131 45
0 2 12 34 131 45
1 2 12 13 118 25
-1 3 12 13 118 25
0 3 12 13 118 25
0 -4 13 34 131 45
-2 -3 13 34 131 45
-1 -3 13 34 131 45
0 -3 13 34 131 45
1 -3 13 34 131 45
-3 -2 13 13 118 25
-2 -2 13 34 131 45
-1 -2 13 34 131 45
0 -2 13 34 131 45
1 -2 13 34 131 45
2 -2 13 34 131 45
-3 -1 13 34 131 45
-2 -1 13 34 131 45
-1 -1 13 34 131 45
0 -1 13 34 131 45
1 -1 13 34 131 45
2 -1 13 13 118 25
-3 0 13 34 131 45
-2 0 13 34 131 45
-1 0 13 34 131 45
0 0 13 34 131 45
1 0 13 34 131 45
2 0 13 34 131 45
-3 1 13 34 131 45
-2 1 13 34 131 45
-1 1 13 34 131 45
0 1 13 34 131 45
1 1 13 34 131 45
2 1 13 34 131 45
-2 2 13 34 131 45
-1 2 13 34 131 45
0 2 13 34 131 45
1 2 13 34 131 45
-2 -3 14 13 118 25
-1 -3 14 34 131 45
0 -3 14 34 131 45
1 -3 14 34 131 45
-3 -2 14 13 118 25
-2 -2 14 34 131 45
-1 -2 14 34 131 45
0 -2 14 34 131 45
1 -2 14 34 131 45
2 -2 14 13 118 25
-3 -1 14 34 131 45
-2 -1 14 34 131 45
-1 -1 14 34 131 45
0 -1 14 34 131 45
1 -1 14 34 131 45
2 -1 14 13 118 25
-3 0 14 34 131 45
-2 0 14 34 131 45
-1 0 14 34 131 45
0 0 14 34 131 45
1 0 14 34 131 45
2 0 14 34 131 45
3 0 14 13 118 25
-3 1 14 34 131 45
-2 1 14 34 131 45
-1 1 14 34 131 45
0 1 14 34 131 45
1 1 14 34 131 45
2 1 14 34 131 45
-2 2 14 34 131 45
-1 2 14 34 131 45
0 2 14 34 131 45
1 2 14 34 131 45
-2 -3 15 34 131 45
-1 -3 15 34 131 45
0 -3 15 34 131 45
1 -3 15 13 118 25
-2 -2 15 34 131 45
-1 -2 15 34 131 45
0 -2 15 34 131 45
1 -2 15 34 131 45
-3 -1 15 13 118 25
-2 -1 15 34 131 45
-1 -1 15 34 131 45
0 -1 15 34 131 45
1 -1 15 34 131 45
2 -1 15 34 131 45
-3 0 15 34 131 45
-2 0 15 34 131 45
-1 0 15 34 131 45
0 0 15 34 131 45
1 0 15 34 131 45
2 0 15 34 131 45
-2 1 15 34 131 45
-1 1 15 34 131 45
0 1 15 34 131 45
1 1 15 34 131 45
2 1 15 34 131 45
-2 2 15 34 131 45
-1 2 15 34 131 45
0 2 15 34 131 45
1 2 15 34 131 45
-2 -3 16 34 131 45
-1 -3 16 34 131 45
0 -3 16 34 131 45
1 -3 16 13 118 25
-2 -2 16 34 131 45
-1 -2 16 34 131 45
0 -2 16 34 131 45
1 -2 16 34 131 45
-3 -1 16 13 118 25
-2 -1 16 34 131 45
-1 -1 16 34 131 45
0 -1 16 34 131 45
1 -1 16 34 131 45
2 -1 16 34 131 45
-3 0 16 34 131 45
-2 0 16 34 131 45
-1 0 16 34 131 45
0 0 16 34 131 45
1 0 16 34 131 45
2 0 16 34 131 45
-2 1 16 34 131 45
-1 1 16 34 131 45
0 1 16 34 131 45
1 1 16 34 131 45
-2 2 16 34 131 45
0 2 16 34 131 45
1 2 16 34 131 45
-2 -3 17 34 131 45
-1 -3 17 34 131 45
0 -3 17 34 131 45
1 -3 17 34 131 45
-2 -2 17 34 131 45
-1 -2 17 34 131 45
0 -2 17 34 131 45
1 -2 17 34 131 45
-3 -1 17 13 118 25
-2 -1 17 34 131 45
-1 -1 17 34 131 45
0 -1 17 34 131 45
1 -1 17 34 131 45
2 -1 17 13 118 25
-2 0 17 34 131 45
-1 0 17 34 131 45
0 0 17 34 131 45
1 0 17 34 131 45
2 0 17 34 131 45
-2 1 17 34 131 45
-1 1 17 34 131 45
0 1 17 34 131 45
1 1 17 34 131 45
-2 2 17 13 118 25
0 2 17 13 118 25
1 2 17 34 131 45
-1 -3 18 34 131 45
0 -3 18 34 131 45
-2 -2 18 34 131 45
-1 -2 18 34 131 45
0 -2 18 34 131 45
1 -2 18 34 131 45
-3 -1 18 13 118 25
-2 -1 18 34 131 45
-1 -1 18 34 131 45
0 -1 18 34 131 45
1 -1 18 34 131 45
2 -1 18 13 118 25
-2 0 18 34 131 45
-1 0 18 34 131 45
0 0 18 34 131 45
1 0 18 34 131 45
2 0 18 13 118 25
-1 1 18 34 131 45
0 1 18 34 131 45
1 1 18 34 131 45
-1 2 18 13 118 25
0 2 18 34 131 45
-1 -2 19 34 131 45
0 -2 19 34 131 45
-2 -1 19 34 131 45
-1 -1 19 34 131 45
0 -1 19 34 131 45
1 -1 19 13 118 25
-2 0 19 34 131 45
-1 0 19 34 131 45
0 0 19 34 131 45
1 0 19 13 118 25
-1 1 19 34 131 45
0 1 19 34 131 45
-1 -2 20 34 131 45
0 -2 20 34 131 45
-1 -1 20 34 131 45
0 -1 20 34 131 45
-1 0 20 34 131 45
0 0 20 34 131 45
1 0 20 34 131 45
-1 1 20 13 118 25
-1 -1 21 34 131 45
0 -1 21 34 131 45
-1 0 21 34 131 45
0 0 21 34 131 45
